Workbook

Sheet Races
N2: Application | P2: Tags
B3: Rank | C3: Rank_mod | D3: Name | E3: City / Race Location | F3: Country | G3: Month | I3: Distance | J3: Cost | K3: Month_adj | L3: Inception | M3: # of finishers | N3: From | O3: To | P3: 9+1 | Q3: 4 out of 6 | R3: Virtual 6
B4: Majors | C4: 1 | D4: Tokyo Marathon | E4: Tokyo | F4: Japan | G4: February | I4: Full | K4: 2 | L4: 1981
B5: Majors | C5: 1 | D5: Boston Marathon | E5: Boston | F5: United States | G5: April | I5: Full | K5: 4 | L5: 1897
B6: Majors | C6: 1 | D6: London Marathon | E6: London | F6: United Kingdom | G6: April | I6: Full | K6: 4 | L6: 1981
B7: Majors | C7: 1 | D7: Berlin Marathon | E7: Berlin | F7: Germany | G7: September | I7: Full | K7: 9 | L7: 1974
B8: Majors | C8: 1 | D8: Sydney Marathon | E8: Sydney | F8: Australia | G8: September | I8: Full | K8: 9 | L8: 2001
B9: Majors | C9: 1 | D9: Chicago Marathon | E9: Chicago | F9: United States | G9: October | H9: 46306 | I9: Full | K9: 10 | L9: 1977
B10: Majors | C10: 1 | D10: New York City Marathon | E10: New York City | F10: United States | G10: November | H10: 46327 | I10: Full | K10: 11 | L10: 1970 | N10: Feb
B11: Platinum | C11: 2 | D11: Osaka Women's Marathon | E11: Osaka | F11: Japan | G11: January | I11: Full | K11: 1 | L11: 1982
B12: Platinum | C12: 2 | D12: Xiamen Marathon | E12: Xiamen | F12: China | G12: January | I12: Full | K12: 1 | L12: 2003
B13: Platinum | C13: 2 | D13: Nagoya Women's Marathon | E13: Nagoya | F13: Japan | G13: March | I13: Full | K13: 3 | L13: 1980
B14: Platinum | C14: 2 | D14: Seoul International Marathon | E14: Seoul | F14: South Korea | G14: March | I14: Full | K14: 3 | L14: 1931
B15: Platinum | C15: 2 | D15: Amsterdam Marathon | E15: Amsterdam | F15: Netherlands | G15: October | I15: Full | K15: 10 | L15: 1975
B16: Platinum | C16: 2 | D16: Shanghai Marathon | E16: Shanghai | F16: China | G16: December | I16: Full | K16: 12 | L16: 2000
B17: Platinum | C17: 2 | D17: Valencia Marathon | E17: Valencia | F17: Spain | G17: December | I17: Full | K17: 12 | L17: 1981
B18: Gold | C18: 3 | D18: Buriram Marathon | E18: Buriram | F18: Thailand | G18: January | I18: Full | K18: 1 | L18: 2017
B19: Gold | C19: 3 | D19: Doha Marathon | E19: Doha | F19: Qatar | G19: January | I19: Full | K19: 1 | L19: 2013
B20: Gold | C20: 3 | D20: Houston Marathon | E20: Houston | F20: United States | G20: January | I20: Full | K20: 1 | L20: 1972
B21: Gold | C21: 3 | D21: Lagos City Marathon | E21: Lagos | F21: Nigeria | G21: January | I21: Full | K21: 1 | L21: 2016
B22: Gold | C22: 3 | D22: Mumbai Marathon | E22: Mumbai | F22: India | G22: January | I22: Full | K22: 1 | L22: 2004
B23: Gold | C23: 3 | D23: Hong Kong Marathon | E23: Hong Kong | F23: Hong Kong | G23: February | I23: Full | K23: 2 | L23: 1997
B24: Gold | C24: 3 | D24: Osaka Marathon | E24: Osaka | F24: Japan | G24: February | I24: Full | K24: 2 | L24: 2011
B25: Gold | C25: 3 | D25: Barcelona Marathon | E25: Barcelona | F25: Spain | G25: March | I25: Full | K25: 3 | L25: 1978
B26: Gold | C26: 3 | D26: New Taipei City Wan Jin Shi Marathon | E26: New Taipei City | F26: Taiwan | G26: March | I26: Full | K26: 3 | L26: 1979
B27: Gold | C27: 3 | D27: Daegu Marathon | E27: Daegu | F27: South Korea | G27: April | I27: Full | K27: 4 | L27: 2009
... B29: Gold | C29: 3 | D29: Mexico City Marathon | E29: Mexico City | F29: Mexico | G29: August | I29: Full | K29: 8 | L29: 1983
B30: Gold | C30: 3 | D30: Beijing Marathon | E30: Beijing | F30: China | G30: October | I30: Full | K30: 10 | L30: 1981
B31: Gold | C31: 3 | D31: Ljubljana Marathon | E31: Ljubljana | F31: Slovenia | G31: October | I31: Full | K31: 10 | L31: 1996
B32: Gold | C32: 3 | D32: Hangzhou International Marathon | E32: Hangzhou | F32: China | G32: November | I32: Full | K32: 11 | L32: 1987
B33: Gold | C33: 3 | D33: Istanbul Marathon | E33: Istanbul | F33: Turkey | G33: November | I33: Full | K33: 11 | L33: 1979
B34: Gold | C34: 3 | D34: Guangzhou Marathon | E34: Guangzhou | F34: China | G34: December | I34: Full | K34: 12 | L34: 2012
B35: Gold | C35: 3 | D35: Singapore Marathon | E35: Singapore | F35: Singapore | G35: December | I35: Full | K35: 12 | L35: 1982
B36: Gold | C36: 3 | D36: Taipei Marathon | E36: Taipei | F36: Taiwan | G36: December | I36: Full | K36: 12 | L36: 2002
B37: Elite | C37: 4 | D37: Beppu-Ōita Marathon | E37: Beppu and Ōita | F37: Japan | G37: February | I37: Full | K37: 2 | L37: 1952
B38: Elite | C38: 4 | D38: Seville Marathon | E38: Seville | F38: Spain | G38: February | I38: Full | K38: 2 | L38: 1985
B39: Elite | C39: 4 | D39: Riyadh Marathon | E39: Riyadh | F39: Saudi Arabia | G39: February/March | I39: Full | K39: 2/3 | L39: 2022
B40: Elite | C40: 4 | D40: Enschede Marathon | E40: Enschede | F40: Netherlands | G40: April | I40: Full | K40: 4 | L40: 1991
B41: Elite | C41: 4 | D41: Paris Marathon | E41: Paris | F41: France | G41: April | I41: Full | K41: 4 | L41: 1976
B42: Elite | C42: 4 | D42: Rome Marathon | E42: Rome | F42: Italy | G42: April | I42: Full | K42: 4 | L42: 1982
...

Sheet Nike training program_42k
C2: Recovery | H2: Recovery | M2: Speed | R2: Recovery | W2: Long | AC2: Recovery | AI2: Recovery | AO2: Speed | AU2: Recovery | BA2: Long
B3: Week | C3: Laps | D3: Category | E3: Pace | F3: Distance | G3: Min | H3: Laps | I3: Category | J3: Pace | K3: Distance | L3: Min | M3: Laps | N3: Category | O3: Pace | P3: Distance | Q3: Min | R3: Laps | S3: Category | T3: Pace | U3: Distance | V3: Min | W3: Laps | X3: Category | Y3: Pace | Z3: Distance | AA3: Min | AC3: Laps | AD3: Category | AE3: Pace | AF3: Distance | AG3: Min | AI3: Laps | AJ3: Category | AK3: Pace | AL3: Distance | AM3: Min | AO3: Laps | AP3: Category | AQ3: Pace | AR3: Distance | AS3: Min | AU3: Laps | AV3: Category | AW3: Pace | AX3: Distance | AY3: Min | BA3: Laps | BB3: Category | BC3: Pace | BD3: Distance | BE3: Min
B4: W-18 | C4: 1 | D4: Recovery | E4: 05:39 | F4: 1.77 | G4: 10:00 | H4: 1 | I4: Warm-up | J4: - | K4: - | L4: 05:00 | M4: 1 | N4: Recovery | O4: - | P4: 3.2 | Q4: - | R4: 1 | S4: Recovery | T4: 05:39 | U4: 1.24 | V4: 07:00 | W4: 1 | X4: Long | Y4: - | Z4: 8 | AA4: - | AC4: 1 | AD4: Recovery | AE4: 05:39 | AF4: 1.8 | AG4: 10:00 | AI4: 1 | AJ4: Warm-up | AK4: - | AL4: - | AM4: 05:00 | AO4: 1 | AP4: Recovery | AQ4: 05:39 | AR4: 3.2 | AS4: - | AU4: 1 | AV4: Recovery | AW4: 05:39 | AX4: 1.2 | AY4: 07:00 | BA4: 1 | BB4: Long | BC4: - | BD4: 8 | BE4: -
H5: 8 | I5: 5k | J5: 04:37 | K5: 0.217 | L5: 01:00 | AI5: 8 | AJ5: 5k | AK5: 04:37 | AL5: 0.2 | AM5: 01:00
H6: 7 | I6: Recovery | J6: 05:39 | K6: 0.177 | L6: 01:00 | AJ6: Recovery | AK6: 05:39 | AL6: 0.2 | AM6: 01:00
B7: W-17 | C7: 1 | D7: Recovery | E7: 05:39 | F7: 2.12 | G7: 12:00 | H7: 1 | I7: Recovery | J7: - | K7: 5 | L7: - | M7: 1 | N7: Warm-up | O7: - | P7: - | Q7: 05:00 | R7: 1 | S7: Recovery | T7: - | U7: 1.6 | V7: - | W7: 1 | X7: Long | Y7: - | Z7: 10 | AA7: - | AC7: 1 | AD7: Recovery | AE7: 05:39 | AF7: 2.1 | AG7: 12:00 | AI7: 1 | AJ7: Recovery | AK7: 05:39 | AL7: 5 | AM7: - | AO7: 1 | AP7: Warm-up | AQ7: - | AR7: - | AS7: 05:00 | AU7: 1 | AV7: Recovery | AW7: 05:39 | AX7: 1.6 | AY7: - | BA7: 1 | BB7: Long | BC7: - | BD7: 10 | BE7: -
M8: 1 | N8: 5k | O8: 04:37 | P8: 0.217 | Q8: 01:00 | AO8: 1 | AP8: 5k | AQ8: 04:37 | AR8: 0.2 | AS8: 01:00
M9: 1 | N9: Recovery | O9: 05:39 | P9: 0.177 | Q9: 01:00 | AP9: Recovery | AQ9: 05:39 | AR9: 0.2 | AS9: 01:00
M10: 1 | N10: 10k | O10: 04:46 | P10: 0.42 | Q10: 02:00 | AO10: 1 | AP10: 10k | AQ10: 04:46 | AR10: 0.4 | AS10: 02:00
M11: 1 | N11: Recovery | O11: 05:39 | P11: 0.177 | Q11: 01:00 | AP11: Recovery | AQ11: 05:39 | AR11: 0.2 | AS11: 01:00
M12: 1 | N12: 5k | O12: 04:37 | P12: 0.217 | Q12: 01:00 | AO12: 1 | AP12: 5k | AQ12: 04:37 | AR12: 0.2 | AS12: 01:00
M13: 1 | N13: Recovery | O13: 05:39 | P13: 0.177 | Q13: 01:00 | AP13: Recovery | AQ13: 05:39 | AR13: 0.2 | AS13: 01:00
M14: 2 | N14: Mile | O14: 04:25 | P14: 0.17 | Q14: 00:45 | AO14: 2 | AP14: Mile | AQ14: 04:25 | AR14: 0.2 | AS14: 00:45
M15: 2 | N15: Recovery | O15: 05:39 | P15: 0.177 | Q15: 01:00 | AP15: Recovery | AQ15: 05:39 | AR15: 0.2 | AS15: 01:00
M16: 1 | N16: 10k | O16: 04:46 | P16: 0.42 | Q16: 02:00 | AO16: 1 | AP16: 10k | AQ16: 04:46 | AR16: 0.4 | AS16: 02:00
M17: 1 | N17: Recovery | O17: 05:39 | P17: 0.177 | Q17: 01:00 | AP17: Recovery | AQ17: 05:39 | AR17: 0.2 | AS17: 01:00
M18: 1 | N18: 5k | O18: 04:37 | P18: 0.217 | Q18: 01:00 | AO18: 1 | AP18: 5k | AQ18: 04:37 | AR18: 0.2 | AS18: 01:00
M19: 1 | N19: Recovery | O19: 05:39 | P19: 0.177 | Q19: 01:00 | AP19: Recovery | AQ19: 05:39 | AR19: 0.2 | AS19: 01:00
M20: 1 | N20: Mile | O20: 04:25 | P20: 0.17 | Q20: 00:45 | AO20: 1 | AP20: Mile | AQ20: 04:25 | AR20: 0.15 | AS20: 00:45
M21: 1 | N21: Recovery | O21: 05:39 | P21: 0.177 | Q21: 01:00 | AP21: Recovery | AQ21: 05:39 | AR21: 0.2 | AS21: 01:00
M22: 1 | N22: Best | O22: 04:13 | P22: 0.119 | Q22: 00:30 | AO22: 1 | AP22: Best | AQ22: 04:13 | AR22: 0.1 | AS22: 00:30
M23: 1 | N23: Recovery | O23: 05:39 | P23: 0.177 | Q23: 01:00 | AP23: Recovery | AQ23: 05:39 | AR23: 0.2 | AS23: 01:00
M24: 1 | N24: Best | O24: 04:13 | P24: 0.059 | Q24: 00:15 | AO24: 1 | AP24: Best | AQ24: 04:13 | AR24: 0.05 | AS24: 00:15
B25: W-16 | C25: 1 | D25: Recovery | E25: 05:39 | F25: 2.65 | G25: 15:00 | H25: 1 | I25: Recovery | J25: - | K25: 5 | L25: - | M25: 1 | N25: Warm-up | O25: - | P25: - | Q25: 05:00 | R25: 1 | S25: Recovery | T25: 05:39 | U25: 4.42 | V25: 25:00 | W25: 1 | X25: Long | Y25: - | Z25: 11.25 | AA25: - | AC25: 1 | AD25: Recovery | AE25: 05:39 | AF25: 2.6 | AG25: 15:00 | AI25: 1 | AJ25: Recovery | AK25: 05:39 | AL25: 5 | AM25: - | AO25: 1 | AP25: Warm-up | AQ25: - | AR25: - | AS25: 05:00 | AU25: 1 | AV25: Recovery | AW25: 05:39 | AX25: 4.4 | AY25: 25:00 | BA25: 1 | BB25: Long | BC25: - | BD25: 11.25 | BE25: -
M26: 7 | N26: 5k | O26: 04:37 | P26: 0.217 | Q26: 01:00 | AO26: 7 | AP26: 5k | AQ26: 04:37 | AR26: 0.2 | AS26: 01:00
M27: 7 | N27: Recovery | O27: 05:39 | P27: 0.354 | Q27: 02:00 | AP27: Recovery | AQ27: 05:39 | AR27: 0.4 | AS27: 02:00
B28: W-15 | C28: 1 | D28: Recovery | E28: 05:39 | F28: 3.54 | G28: 20:00 | H28: 1 | I28: Recovery | J28: 05:39 | K28: 5.31 | L28: 30:00 | M28: 1 | N28: Hill | O28: - | P28: - | Q28: 05:00 | R28: 1 | S28: Recovery | T28: 05:39 | U28: 6.19 | V28: 35:00 | W28: 1 | X28: Long | Y28: - | Z28: 10 | AA28: - | AC28: 1 | AD28: Recovery | AE28: 05:39 | AF28: 3.5 | AG28: 20:00 | AI28: 1 | AJ28: Recovery | AK28: 05:39 | AL28: 5.3 | AM28: 30:00 | AO28: 1 | AP28: Hill | AQ28: - | AR28: - | AS28: 05:00 | AU28: 1 | AV28: Recovery | AW28: 05:39 | AX28: 6.2 | AY28: 35:00 | BA28: 1 | BB28: Long | BC28: - | BD28: 10 | BE28: -
M29: 5 | N29: 10k | O29: 04:46 | P29: 0.157 | Q29: 00:45 | AO29: 5 | AP29: 10k | AQ29: 04:46 | AR29: 0.15 | AS29: 00:45
M30: 5 | N30: Recovery | O30: 05:39 | P30: 0.221 | Q30: 01:15 | AP30: Recovery | AQ30: 05:39 | AR30: 0.2 | AS30: 01:15
M31: 5 | N31: Best | O31: 04:13 | P31: 0.059 | Q31: 00:15 | AO31: 5 | AP31: Best | AQ31: 04:13 | AR31: 0.05 | AS31: 00:15
M32: 5 | N32: Recovery | O32: 05:39 | P32: 0.133 | Q32: 00:45 | AP32: Recovery | AQ32: 05:39 | AR32: 0.15 | AS32: 00:45
B33: W-14 | C33: 1 | D33: Recovery | E33: 05:39 | F33: 4.42 | G33: 25:00 | H33: 1 | I33: Recovery | J33: 05:39 | K33: 7.08 | L33: 40:00 | M33: 1 | N33: Warm-up | O33: - | P33: - | Q33: 07:00 | R33: 1 | S33: Recovery | T33: 05:39 | U33: 7.96 | V33: 45:00 | W33: 1 | X33: Long | Y33: - | Z33: 13 | AA33: - | AC33: 1 | AD33: Recovery | AE33: 05:39 | AF33: 4.4 | AG33: 25:00 | AI33: 1 | AJ33: Recovery | AK33: 05:39 | AL33: 7.1 | AM33: 40:00 | AO33: 1 | AP33: Warm-up | AQ33: - | AR33: - | AS33: 07:00 | AU33: 1 | AV33: Recovery | AW33: 05:39 | AX33: 8 | AY33: 45:00 | BA33: 1 | BB33: Long | BC33: - | BD33: 13 | BE33: -
M34: 3 | N34: 5k | O34: 04:37 | P34: 0.433 | Q34: 02:00 | AO34: 3 | AP34: 5k | AQ34: 04:37 | AR34: 0.4 | AS34: 02:00
M35: 3 | N35: Recovery | O35: 05:39 | P35: 0.177 | Q35: 01:00 | AP35: Recovery | AQ35: 05:39 | AR35: 0.2 | AS35: 01:00
M36: 1 | N36: Tempo | O36: 04:59 | P36: 2.01 | Q36: 10:00 | AO36: 1 | AP36: Tempo | AQ36: 04:59 | AR36: 2 | AS36: 10:00
M37: 1 | N37: Recovery | O37: 05:39 | P37: 0.354 | Q37: 02:00 | AO37: 1 | AP37: Recovery | AQ37: 05:39 | AR37: 0.4 | AS37: 02:00
M38: 3 | N38: 5k | O38: 04:37 | P38: 0.433 | Q38: 02:00 | AP38: 5k | AQ38: 04:37 | AR38: 0.4 | AS38: 02:00
B39: W-13 | C39: 1 | D39: Recovery | E39: 05:39 | F39: 5.31 | G39: 30:00 | H39: 1 | I39: Recovery | J39: 05:39 | K39: 6.19 | L39: 35:00 | M39: 1 | N39: Warm-up | O39: - | P39: - | Q39: 05:00 | R39: 1 | S39: Recovery | T39: 05:39 | U39: 7.96 | V39: 45:00 | W39: 1 | X39: Long | Y39: - | Z39: 16 | AA39: - | AC39: 1 | AD39: Recovery | AE39: 05:39 | AF39: 5.3 | AG39: 30:00 | AI39: 1 | AJ39: Recovery | AK39: 05:39 | AL39: 6.2 | AM39: 35:00 | AO39: 1 | AP39: Warm-up | AQ39: - | AR39: - | AS39: 05:00 | AU39: 1 | AV39: Recovery | AW39: 05:39 | AX39: 8 | AY39: 45:00 | BA39: 1 | BB39: Long | BC39: - | BD39: 16 | BE39: -
M40: 3 | N40: 5k | O40: 04:37 | P40: 0.65 | Q40: 03:00 | AO40: 3 | AP40: 5k | AQ40: 04:37 | AR40: 0.7 | AS40: 03:00
M41: 3 | N41: Recovery | O41: 05:39 | P41: 0.354 | Q41: 02:00 | AP41: Recovery | AQ41: 05:39 | AR41: 0.4 | AS41: 02:00
...

Sheet Nike pace chart
B2: mile to km | D2: 1.60934 | E2: 60
D4: 5k | G4: 10k | I4: Tempo | K4: Half | N4: Full | P4: Recovery | V4: 5k | AI4: 10k | AO4: Tempo | AT4: Half | AZ4: Full | BG4: Recovery
B5: Mile best | C5: 5k best/avg mile pace | D5: Total | E5: Avg. | F5: 10k best/ avg mile pace | G5: Total | H5: Avg. | I5: tempo avg mile pace | J5: half marathon best/avg mile pace | K5: Total | L5: Avg. | M5: marathon best/ avg mile pace | N5: Total | O5: Avg. | P5: recovery day pace | Q5: Best | R5: Min | S5: Seconds | U5: Diff | V5: Total | W5: Min | X5: Seconds | AA5: Diff | AD5: Avg. | AE5: Min | AF5: Seconds | AH5: Diff | AI5: Total | AJ5: Avg. | AK5: Min | AL5: Seconds | AN5: Diff | AO5: tempo avg mile pace | AP5: Min | AQ5: Seconds | AS5: Diff | AT5: Total | AU5: Avg. | AV5: Min | AW5: Seconds | AY5: Diff | AZ5: Total | BA5: Avg. | BB5: Min | BC5: Seconds | BE5: Diff | BG5: recovery day pace | BH5: Min | BI5: Seconds | BK5: Diff
B6: 5:00 | C6: 17:05/5:30 | D6: 17:05 | E6: 5:30 | F6: 35:45/5:45 | G6: 35:45 | H6: 5:45 | I6: 6:05 | J6: 1:18:00/6:00 | K6: 1:18:00 | L6: 6:00 | M6: 2:44:00/ 6:15 | N6: 2:44:00 | O6: 6:15 | P6: 7:00 | Q6: =QUOTIENT((_xlfn.TEXTBEFORE(B6,":")*$E$2+_xlfn.TEXTAFTER(B6,":"))/$D$2,$E$2)&":"&TEXT(MOD((_xlfn.TEXTBEFORE(B6,":")*$E$2+_xlfn.TEXTAFTER(B6,":"))/$D$2,$E$2),"00") -> 3:06 | R6: =_xlfn.TEXTBEFORE(Q6,":") -> 3 | S6: =_xlfn.TEXTAFTER(Q6,":") -> 06 | T6: =R6*60+S6 -> 186 | U6: =T7-T6 -> 19 | V6: =D6 -> 17:05 | W6: =_xlfn.TEXTBEFORE(V6,":") -> 17 | X6: =_xlfn.TEXTAFTER(V6,":") -> 05 | Y6: =W6*60+X6 -> 1025 | Z6: =IF(AND(Y6>$BR$8,SUM($Z$5:Z5)=0),1,0) -> 0 | AA6: =Y7-Y6 -> 100 | AB6: =IF(Z7=1,$BR$8-Y6,0) -> 0 | AC6: =AB6/AA6 -> 0 | AD6: =QUOTIENT((_xlfn.TEXTBEFORE(E6,":")*$E$2+_xlfn.TEXTAFTER(E6,":"))/$D$2,$E$2)&":"&TEXT(MOD((_xlfn.TEXTBEFORE(E6,":")*$E$2+_xlfn.TEXTAFTER(E6,":"))/$D$2,$E$2),"00") -> 3:25 | AE6: =_xlfn.TEXTBEFORE(AD6,":") -> 3 | AF6: =_xlfn.TEXTAFTER(AD6,":") -> 25 | AG6: =AE6*60+AF6 -> 205 | AH6: =AG7-AG6 -> 19 | AI6: =G6 -> 35:45 | AJ6: =QUOTIENT((_xlfn.TEXTBEFORE(H6,":")*$E$2+_xlfn.TEXTAFTER(H6,":"))/$D$2,$E$2)&":"&TEXT(MOD((_xlfn.TEXTBEFORE(H6,":")*$E$2+_xlfn.TEXTAFTER(H6,":"))/$D$2,$E$2),"00") -> 3:34 | AK6: =_xlfn.TEXTBEFORE(AJ6,":") -> 3 | AL6: =_xlfn.TEXTAFTER(AJ6,":") -> 34 | AM6: =AK6*60+AL6 -> 214 | AN6: =AM7-AM6 -> 19 | AO6: =QUOTIENT((_xlfn.TEXTBEFORE(I6,":")*$E$2+_xlfn.TEXTAFTER(I6,":"))/$D$2,$E$2)&":"&TEXT(MOD((_xlfn.TEXTBEFORE(I6,":")*$E$2+_xlfn.TEXTAFTER(I6,":"))/$D$2,$E$2),"00") -> 3:47 | AP6: =_xlfn.TEXTBEFORE(AO6,":") -> 3 | AQ6: =_xlfn.TEXTAFTER(AO6,":") -> 47 | AR6: =AP6*60+AQ6 -> 227 | AS6: =AR7-AR6 -> 18 | AT6: =K6 -> 1:18:00 | AU6: =QUOTIENT((_xlfn.TEXTBEFORE(L6,":")*$E$2+_xlfn.TEXTAFTER(L6,":"))/$D$2,$E$2)&":"&TEXT(MOD((_xlfn.TEXTBEFORE(L6,":")*$E$2+_xlfn.TEXTAFTER(L6,":"))/$D$2,$E$2),"00") -> 3:44 | AV6: =_xlfn.TEXTBEFORE(AU6,":") -> 3 | AW6: =_xlfn.TEXTAFTER(AU6,":") -> 44 | AX6: =AV6*60+AW6 -> 224 | AY6: =AX7-AX6 -> 18 | AZ6: =N6 -> 2:44:00 | BA6: =QUOTIENT((_xlfn.TEXTBEFORE(O6,":")*$E$2+_xlfn.TEXTAFTER(O6,":"))/$D$2,$E$2)&":"&TEXT(MOD((_xlfn.TEXTBEFORE(O6,":")*$E$2+_xlfn.TEXTAFTER(O6,":"))/$D$2,$E$2),"00") -> 3:53 | BB6: =_xlfn.TEXTBEFORE(BA6,":") -> 3 | BC6: =_xlfn.TEXTAFTER(BA6,":") -> 53 | BD6: =BB6*60+BC6 -> 233 | BE6: =BD7-BD6 -> 22 | BF6: =BB6*60+BC6 -> 233 | BG6: =QUOTIENT((_xlfn.TEXTBEFORE(P6,":")*$E$2+_xlfn.TEXTAFTER(P6,":"))/$D$2,$E$2)&":"&TEXT(MOD((_xlfn.TEXTBEFORE(P6,":")*$E$2+_xlfn.TEXTAFTER(P6,":"))/$D$2,$E$2),"00") -> 4:21 | BH6: =_xlfn.TEXTBEFORE(BG6,":") -> 4 | BI6: =_xlfn.TEXTAFTER(BG6,":") -> 21 | BJ6: =BH6*60+BI6 -> 261 | BK6: =BJ7-BJ6 -> 22
B7: 5:30 | C7: 18:45/6:00 | D7: 18:45 | E7: 6:00 | F7: 39:00/6:15 | G7: 39:00 | H7: 6:15 | I7: 6:35 | J7: 1:25:00/6:30 | K7: 1:25:00 | L7: 6:30 | M7: 3:00:00/6:50 | N7: 3:00:00 | O7: 6:50 | P7: 7:35 | Q7: =QUOTIENT((_xlfn.TEXTBEFORE(B7,":")*$E$2+_xlfn.TEXTAFTER(B7,":"))/$D$2,$E$2)&":"&TEXT(MOD((_xlfn.TEXTBEFORE(B7,":")*$E$2+_xlfn.TEXTAFTER(B7,":"))/$D$2,$E$2),"00") -> 3:25 | R7: =_xlfn.TEXTBEFORE(Q7,":") -> 3 | S7: =_xlfn.TEXTAFTER(Q7,":") -> 25 | T7: =R7*60+S7 -> 205 | U7: =T8-T7 -> 19 | V7: =D7 -> 18:45 | W7: =_xlfn.TEXTBEFORE(V7,":") -> 18 | X7: =_xlfn.TEXTAFTER(V7,":") -> 45 | Y7: =W7*60+X7 -> 1125 | Z7: =IF(AND(Y7>$BR$8,SUM($Z$5:Z6)=0),1,0) -> 0 | AA7: =Y8-Y7 -> 90 | AB7: =IF(Z8=1,$BR$8-Y7,0) -> 0 | AC7: =AB7/AA7 -> 0 | AD7: =QUOTIENT((_xlfn.TEXTBEFORE(E7,":")*$E$2+_xlfn.TEXTAFTER(E7,":"))/$D$2,$E$2)&":"&TEXT(MOD((_xlfn.TEXTBEFORE(E7,":")*$E$2+_xlfn.TEXTAFTER(E7,":"))/$D$2,$E$2),"00") -> 3:44 | AE7: =_xlfn.TEXTBEFORE(AD7,":") -> 3 | AF7: =_xlfn.TEXTAFTER(AD7,":") -> 44 | AG7: =AE7*60+AF7 -> 224 | AH7: =AG8-AG7 -> 18 | AI7: =G7 -> 39:00 | AJ7: =QUOTIENT((_xlfn.TEXTBEFORE(H7,":")*$E$2+_xlfn.TEXTAFTER(H7,":"))/$D$2,$E$2)&":"&TEXT(MOD((_xlfn.TEXTBEFORE(H7,":")*$E$2+_xlfn.TEXTAFTER(H7,":"))/$D$2,$E$2),"00") -> 3:53 | AK7: =_xlfn.TEXTBEFORE(AJ7,":") -> 3 | AL7: =_xlfn.TEXTAFTER(AJ7,":") -> 53 | AM7: =AK7*60+AL7 -> 233 | AN7: =AM8-AM7 -> 19 | AO7: =QUOTIENT((_xlfn.TEXTBEFORE(I7,":")*$E$2+_xlfn.TEXTAFTER(I7,":"))/$D$2,$E$2)&":"&TEXT(MOD((_xlfn.TEXTBEFORE(I7,":")*$E$2+_xlfn.TEXTAFTER(I7,":"))/$D$2,$E$2),"00") -> 4:05 | AP7: =_xlfn.TEXTBEFORE(AO7,":") -> 4 | AQ7: =_xlfn.TEXTAFTER(AO7,":") -> 05 | AR7: =AP7*60+AQ7 -> 245 | AS7: =AR8-AR7 -> 19 | AT7: =K7 -> 1:25:00 | AU7: =QUOTIENT((_xlfn.TEXTBEFORE(L7,":")*$E$2+_xlfn.TEXTAFTER(L7,":"))/$D$2,$E$2)&":"&TEXT(MOD((_xlfn.TEXTBEFORE(L7,":")*$E$2+_xlfn.TEXTAFTER(L7,":"))/$D$2,$E$2),"00") -> 4:02 | AV7: =_xlfn.TEXTBEFORE(AU7,":") -> 4 | AW7: =_xlfn.TEXTAFTER(AU7,":") -> 02 | AX7: =AV7*60+AW7 -> 242 | AY7: =AX8-AX7 -> 28 | AZ7: =N7 -> 3:00:00 | BA7: =QUOTIENT((_xlfn.TEXTBEFORE(O7,":")*$E$2+_xlfn.TEXTAFTER(O7,":"))/$D$2,$E$2)&":"&TEXT(MOD((_xlfn.TEXTBEFORE(O7,":")*$E$2+_xlfn.TEXTAFTER(O7,":"))/$D$2,$E$2),"00") -> 4:15 | BB7: =_xlfn.TEXTBEFORE(BA7,":") -> 4 | BC7: =_xlfn.TEXTAFTER(BA7,":") -> 15 | BD7: =BB7*60+BC7 -> 255 | BE7: =BD8-BD7 -> 22 | BF7: =BB7*60+BC7 -> 255 | BG7: =QUOTIENT((_xlfn.TEXTBEFORE(P7,":")*$E$2+_xlfn.TEXTAFTER(P7,":"))/$D$2,$E$2)&":"&TEXT(MOD((_xlfn.TEXTBEFORE(P7,":")*$E$2+_xlfn.TEXTAFTER(P7,":"))/$D$2,$E$2),"00") -> 4:43 | BH7: =_xlfn.TEXTBEFORE(BG7,":") -> 4 | BI7: =_xlfn.TEXTAFTER(BG7,":") -> 43 | BJ7: =BH7*60+BI7 -> 283 | BK7: =BJ8-BJ7 -> 21 | BN7: Run | BO7: Avg. | BP7: Min | BQ7: Sec | BR7: Total sec | BV7: Distance | BW7: km/h | BX7: Total
B8: 6:00 | C8: 20:15/6:30 | D8: 20:15 | E8: 6:30 | F8: 42:00/6:45 | G8: 42:00 | H8: 6:45 | I8: 7:05 | J8: 1:35:00/7:15 | K8: 1:35:00 | L8: 7:15 | M8: 3:15:00/7:25 | N8: 3:15:00 | O8: 7:25 | P8: 8:10 | Q8: =QUOTIENT((_xlfn.TEXTBEFORE(B8,":")*$E$2+_xlfn.TEXTAFTER(B8,":"))/$D$2,$E$2)&":"&TEXT(MOD((_xlfn.TEXTBEFORE(B8,":")*$E$2+_xlfn.TEXTAFTER(B8,":"))/$D$2,$E$2),"00") -> 3:44 | R8: =_xlfn.TEXTBEFORE(Q8,":") -> 3 | S8: =_xlfn.TEXTAFTER(Q8,":") -> 44 | T8: =R8*60+S8 -> 224 | U8: =T9-T8 -> 18 | V8: =D8 -> 20:15 | W8: =_xlfn.TEXTBEFORE(V8,":") -> 20 | X8: =_xlfn.TEXTAFTER(V8,":") -> 15 | Y8: =W8*60+X8 -> 1215 | Z8: =IF(AND(Y8>$BR$8,SUM($Z$5:Z7)=0),1,0) -> 0 | AA8: =Y9-Y8 -> 105 | AB8: =IF(Z9=1,$BR$8-Y8,0) -> 0 | AC8: =AB8/AA8 -> 0 | AD8: =QUOTIENT((_xlfn.TEXTBEFORE(E8,":")*$E$2+_xlfn.TEXTAFTER(E8,":"))/$D$2,$E$2)&":"&TEXT(MOD((_xlfn.TEXTBEFORE(E8,":")*$E$2+_xlfn.TEXTAFTER(E8,":"))/$D$2,$E$2),"00") -> 4:02 | AE8: =_xlfn.TEXTBEFORE(AD8,":") -> 4 | AF8: =_xlfn.TEXTAFTER(AD8,":") -> 02 | AG8: =AE8*60+AF8 -> 242 | AH8: =AG9-AG8 -> 22 | AI8: =G8 -> 42:00 | AJ8: =QUOTIENT((_xlfn.TEXTBEFORE(H8,":")*$E$2+_xlfn.TEXTAFTER(H8,":"))/$D$2,$E$2)&":"&TEXT(MOD((_xlfn.TEXTBEFORE(H8,":")*$E$2+_xlfn.TEXTAFTER(H8,":"))/$D$2,$E$2),"00") -> 4:12 | AK8: =_xlfn.TEXTBEFORE(AJ8,":") -> 4 | AL8: =_xlfn.TEXTAFTER(AJ8,":") -> 12 | AM8: =AK8*60+AL8 -> 252 | AN8: =AM9-AM8 -> 21 | AO8: =QUOTIENT((_xlfn.TEXTBEFORE(I8,":")*$E$2+_xlfn.TEXTAFTER(I8,":"))/$D$2,$E$2)&":"&TEXT(MOD((_xlfn.TEXTBEFORE(I8,":")*$E$2+_xlfn.TEXTAFTER(I8,":"))/$D$2,$E$2),"00") -> 4:24 | AP8: =_xlfn.TEXTBEFORE(AO8,":") -> 4 | AQ8: =_xlfn.TEXTAFTER(AO8,":") -> 24 | AR8: =AP8*60+AQ8 -> 264 | AS8: =AR9-AR8 -> 22 | AT8: =K8 -> 1:35:00 | AU8: =QUOTIENT((_xlfn.TEXTBEFORE(L8,":")*$E$2+_xlfn.TEXTAFTER(L8,":"))/$D$2,$E$2)&":"&TEXT(MOD((_xlfn.TEXTBEFORE(L8,":")*$E$2+_xlfn.TEXTAFTER(L8,":"))/$D$2,$E$2),"00") -> 4:30 | AV8: =_xlfn.TEXTBEFORE(AU8,":") -> 4 | AW8: =_xlfn.TEXTAFTER(AU8,":") -> 30 | AX8: =AV8*60+AW8 -> 270 | AY8: =AX9-AX8 -> 13 | AZ8: =N8 -> 3:15:00 | BA8: =QUOTIENT((_xlfn.TEXTBEFORE(O8,":")*$E$2+_xlfn.TEXTAFTER(O8,":"))/$D$2,$E$2)&":"&TEXT(MOD((_xlfn.TEXTBEFORE(O8,":")*$E$2+_xlfn.TEXTAFTER(O8,":"))/$D$2,$E$2),"00") -> 4:37 | BB8: =_xlfn.TEXTBEFORE(BA8,":") -> 4 | BC8: =_xlfn.TEXTAFTER(BA8,":") -> 37 | BD8: =BB8*60+BC8 -> 277 | BE8: =BD9-BD8 -> 21 | BF8: =BB8*60+BC8 -> 277 | BG8: =QUOTIENT((_xlfn.TEXTBEFORE(P8,":")*$E$2+_xlfn.TEXTAFTER(P8,":"))/$D$2,$E$2)&":"&TEXT(MOD((_xlfn.TEXTBEFORE(P8,":")*$E$2+_xlfn.TEXTAFTER(P8,":"))/$D$2,$E$2),"00") -> 5:04 | BH8: =_xlfn.TEXTBEFORE(BG8,":") -> 5 | BI8: =_xlfn.TEXTAFTER(BG8,":") -> 04 | BJ8: =BH8*60+BI8 -> 304 | BK8: =BJ9-BJ8 -> 22 | BM8: Input | BN8: 5k total | BO8: 23:01 | BP8: =_xlfn.TEXTBEFORE(BO8,":") -> 23 | BQ8: =_xlfn.TEXTAFTER(BO8,":") -> 01 | BR8: =BP8*60+BQ8 -> 1381
B9: 6:30 | C9: 22:00/7:05 | D9: 22:00 | E9: 7:05 | F9: 45:45/7:20 | G9: 45:45 | H9: 7:20 | I9: 7:40 | J9: 1:40:00/7:35 | K9: 1:40:00 | L9: 7:35 | M9: 3:30:00/8:00 | N9: 3:30:00 | O9: 8:00 | P9: 8:45 | Q9: =QUOTIENT((_xlfn.TEXTBEFORE(B9,":")*$E$2+_xlfn.TEXTAFTER(B9,":"))/$D$2,$E$2)&":"&TEXT(MOD((_xlfn.TEXTBEFORE(B9,":")*$E$2+_xlfn.TEXTAFTER(B9,":"))/$D$2,$E$2),"00") -> 4:02 | R9: =_xlfn.TEXTBEFORE(Q9,":") -> 4 | S9: =_xlfn.TEXTAFTER(Q9,":") -> 02 | T9: =R9*60+S9 -> 242 | U9: =T10-T9 -> 19 | V9: =D9 -> 22:00 | W9: =_xlfn.TEXTBEFORE(V9,":") -> 22 | X9: =_xlfn.TEXTAFTER(V9,":") -> 00 | Y9: =W9*60+X9 -> 1320 | Z9: =IF(AND(Y9>$BR$8,SUM($Z$5:Z8)=0),1,0) -> 0 | AA9: =Y10-Y9 -> 105 | AB9: =IF(Z10=1,$BR$8-Y9,0) -> 61 | AC9: =AB9/AA9 -> 0.58095238 | AD9: =QUOTIENT((_xlfn.TEXTBEFORE(E9,":")*$E$2+_xlfn.TEXTAFTER(E9,":"))/$D$2,$E$2)&":"&TEXT(MOD((_xlfn.TEXTBEFORE(E9,":")*$E$2+_xlfn.TEXTAFTER(E9,":"))/$D$2,$E$2),"00") -> 4:24 | AE9: =_xlfn.TEXTBEFORE(AD9,":") -> 4 | AF9: =_xlfn.TEXTAFTER(AD9,":") -> 24 | AG9: =AE9*60+AF9 -> 264 | AH9: =AG10-AG9 -> 22 | AI9: =G9 -> 45:45 | AJ9: =QUOTIENT((_xlfn.TEXTBEFORE(H9,":")*$E$2+_xlfn.TEXTAFTER(H9,":"))/$D$2,$E$2)&":"&TEXT(MOD((_xlfn.TEXTBEFORE(H9,":")*$E$2+_xlfn.TEXTAFTER(H9,":"))/$D$2,$E$2),"00") -> 4:33 | AK9: =_xlfn.TEXTBEFORE(AJ9,":") -> 4 | AL9: =_xlfn.TEXTAFTER(AJ9,":") -> 33 | AM9: =AK9*60+AL9 -> 273 | AN9: =AM10-AM9 -> 22 | AO9: =QUOTIENT((_xlfn.TEXTBEFORE(I9,":")*$E$2+_xlfn.TEXTAFTER(I9,":"))/$D$2,$E$2)&":"&TEXT(MOD((_xlfn.TEXTBEFORE(I9,":")*$E$2+_xlfn.TEXTAFTER(I9,":"))/$D$2,$E$2),"00") -> 4:46 | AP9: =_xlfn.TEXTBEFORE(AO9,":") -> 4 | AQ9: =_xlfn.TEXTAFTER(AO9,":") -> 46 | AR9: =AP9*60+AQ9 -> 286 | AS9: =AR10-AR9 -> 22 | AT9: =K9 -> 1:40:00 | AU9: =QUOTIENT((_xlfn.TEXTBEFORE(L9,":")*$E$2+_xlfn.TEXTAFTER(L9,":"))/$D$2,$E$2)&":"&TEXT(MOD((_xlfn.TEXTBEFORE(L9,":")*$E$2+_xlfn.TEXTAFTER(L9,":"))/$D$2,$E$2),"00") -> 4:43 | AV9: =_xlfn.TEXTBEFORE(AU9,":") -> 4 | AW9: =_xlfn.TEXTAFTER(AU9,":") -> 43 | AX9: =AV9*60+AW9 -> 283 | AY9: =AX10-AX9 -> 28 | AZ9: =N9 -> 3:30:00 | BA9: =QUOTIENT((_xlfn.TEXTBEFORE(O9,":")*$E$2+_xlfn.TEXTAFTER(O9,":"))/$D$2,$E$2)&":"&TEXT(MOD((_xlfn.TEXTBEFORE(O9,":")*$E$2+_xlfn.TEXTAFTER(O9,":"))/$D$2,$E$2),"00") -> 4:58 | BB9: =_xlfn.TEXTBEFORE(BA9,":") -> 4 | BC9: =_xlfn.TEXTAFTER(BA9,":") -> 58 | BD9: =BB9*60+BC9 -> 298 | BE9: =BD10-BD9 -> 22 | BF9: =BB9*60+BC9 -> 298 | BG9: =QUOTIENT((_xlfn.TEXTBEFORE(P9,":")*$E$2+_xlfn.TEXTAFTER(P9,":"))/$D$2,$E$2)&":"&TEXT(MOD((_xlfn.TEXTBEFORE(P9,":")*$E$2+_xlfn.TEXTAFTER(P9,":"))/$D$2,$E$2),"00") -> 5:26 | BH9: =_xlfn.TEXTBEFORE(BG9,":") -> 5 | BI9: =_xlfn.TEXTAFTER(BG9,":") -> 26 | BJ9: =BH9*60+BI9 -> 326 | BK9: =BJ10-BJ9 -> 22 | BM9: Output | BN9: Best | BO9: =TEXT(BP9,"00")&":"&TEXT(BQ9,"00") -> 04:13 | BP9: =QUOTIENT(BR9,$E$2) -> 4 | BQ9: =MOD(BR9,$E$2) -> 13.038095 | BR9: =BS9+BT9 -> 253.0381 | BS9: {=INDEX($T$6:$T$20,MATCH(1,$Z$6:$Z$20,0)-1)} -> 242 | BT9: =SUMPRODUCT($U$6:$U$19,$AC$6:$AC$19) -> 11.038095 | BV9: =ROUND(1/BR9*60*1000,-1) -> 240 | BW9: =3600/BR9 -> 14.227107 | BY9: Best
B10: 7:00 | C10: 23:45/7:40 | D10: 23:45 | E10: 7:40 | F10: 49:00/7:55 | G10: 49:00 | H10: 7:55 | I10: 8:15 | J10: 1:50:00/8:20 | K10: 1:50:00 | L10: 8:20 | M10: 3:45:00/8:35 | N10: 3:45:00 | O10: 8:35 | P10: 9:20 | Q10: =QUOTIENT((_xlfn.TEXTBEFORE(B10,":")*$E$2+_xlfn.TEXTAFTER(B10,":"))/$D$2,$E$2)&":"&TEXT(MOD((_xlfn.TEXTBEFORE(B10,":")*$E$2+_xlfn.TEXTAFTER(B10,":"))/$D$2,$E$2),"00") -> 4:21 | R10: =_xlfn.TEXTBEFORE(Q10,":") -> 4 | S10: =_xlfn.TEXTAFTER(Q10,":") -> 21 | T10: =R10*60+S10 -> 261 | U10: =T11-T10 -> 19 | V10: =D10 -> 23:45 | W10: =_xlfn.TEXTBEFORE(V10,":") -> 23 | X10: =_xlfn.TEXTAFTER(V10,":") -> 45 | Y10: =W10*60+X10 -> 1425 | Z10: =IF(AND(Y10>$BR$8,SUM($Z$5:Z9)=0),1,0) -> 1 | AA10: =Y11-Y10 -> 90 | AB10: =IF(Z11=1,$BR$8-Y10,0) -> 0 | AC10: =AB10/AA10 -> 0 | AD10: =QUOTIENT((_xlfn.TEXTBEFORE(E10,":")*$E$2+_xlfn.TEXTAFTER(E10,":"))/$D$2,$E$2)&":"&TEXT(MOD((_xlfn.TEXTBEFORE(E10,":")*$E$2+_xlfn.TEXTAFTER(E10,":"))/$D$2,$E$2),"00") -> 4:46 | AE10: =_xlfn.TEXTBEFORE(AD10,":") -> 4 | AF10: =_xlfn.TEXTAFTER(AD10,":") -> 46 | AG10: =AE10*60+AF10 -> 286 | AH10: =AG11-AG10 -> 15 | AI10: =G10 -> 49:00 | AJ10: =QUOTIENT((_xlfn.TEXTBEFORE(H10,":")*$E$2+_xlfn.TEXTAFTER(H10,":"))/$D$2,$E$2)&":"&TEXT(MOD((_xlfn.TEXTBEFORE(H10,":")*$E$2+_xlfn.TEXTAFTER(H10,":"))/$D$2,$E$2),"00") -> 4:55 | AK10: =_xlfn.TEXTBEFORE(AJ10,":") -> 4 | AL10: =_xlfn.TEXTAFTER(AJ10,":") -> 55 | AM10: =AK10*60+AL10 -> 295 | AN10: =AM11-AM10 -> 19 | AO10: =QUOTIENT((_xlfn.TEXTBEFORE(I10,":")*$E$2+_xlfn.TEXTAFTER(I10,":"))/$D$2,$E$2)&":"&TEXT(MOD((_xlfn.TEXTBEFORE(I10,":")*$E$2+_xlfn.TEXTAFTER(I10,":"))/$D$2,$E$2),"00") -> 5:08 | AP10: =_xlfn.TEXTBEFORE(AO10,":") -> 5 | AQ10: =_xlfn.TEXTAFTER(AO10,":") -> 08 | AR10: =AP10*60+AQ10 -> 308 | AS10: =AR11-AR10 -> 21 | AT10: =K10 -> 1:50:00 | AU10: =QUOTIENT((_xlfn.TEXTBEFORE(L10,":")*$E$2+_xlfn.TEXTAFTER(L10,":"))/$D$2,$E$2)&":"&TEXT(MOD((_xlfn.TEXTBEFORE(L10,":")*$E$2+_xlfn.TEXTAFTER(L10,":"))/$D$2,$E$2),"00") -> 5:11 | AV10: =_xlfn.TEXTBEFORE(AU10,":") -> 5 | AW10: =_xlfn.TEXTAFTER(AU10,":") -> 11 | AX10: =AV10*60+AW10 -> 311 | AY10: =AX11-AX10 -> 15 | AZ10: =N10 -> 3:45:00 | BA10: =QUOTIENT((_xlfn.TEXTBEFORE(O10,":")*$E$2+_xlfn.TEXTAFTER(O10,":"))/$D$2,$E$2)&":"&TEXT(MOD((_xlfn.TEXTBEFORE(O10,":")*$E$2+_xlfn.TEXTAFTER(O10,":"))/$D$2,$E$2),"00") -> 5:20 | BB10: =_xlfn.TEXTBEFORE(BA10,":") -> 5 | BC10: =_xlfn.TEXTAFTER(BA10,":") -> 20 | BD10: =BB10*60+BC10 -> 320 | BE10: =BD11-BD10 -> 22 | BF10: =BB10*60+BC10 -> 320 | BG10: =QUOTIENT((_xlfn.TEXTBEFORE(P10,":")*$E$2+_xlfn.TEXTAFTER(P10,":"))/$D$2,$E$2)&":"&TEXT(MOD((_xlfn.TEXTBEFORE(P10,":")*$E$2+_xlfn.TEXTAFTER(P10,":"))/$D$2,$E$2),"00") -> 5:48 | BH10: =_xlfn.TEXTBEFORE(BG10,":") -> 5 | BI10: =_xlfn.TEXTAFTER(BG10,":") -> 48 | BJ10: =BH10*60+BI10 -> 348 | BK10: =BJ11-BJ10 -> 22 | BN10: Mile | BO10: =TEXT(BP10,"00")&":"&TEXT(BQ10,"00") -> 04:25 | BP10: =QUOTIENT(BR10,$E$2) -> 4 | BQ10: =MOD(BR10,$E$2) -> 24.909524 | BR10: =AVERAGE(BR9,BR11) -> 264.90952 | BU10: 1.60934 | BV10: =ROUND(1/BR10*60*1000,-1) -> 230 | BW10: =3600/BR10 -> 13.589545 | BX10: =TIME(,,BR10*BU10) -> 0.0049305556 | BY10: Mile
B11: 7:30 | C11: 25:15/8:05 | D11: 25:15 | E11: 8:05 | F11: 52:30/8:25 | G11: 52:30 | H11: 8:25 | I11: 8:50 | J11: 1:55:00/8:45 | K11: 1:55:00 | L11: 8:45 | M11: 4:00:00/9:10 | N11: 4:00:00 | O11: 9:10 | P11: 9:55 | Q11: =QUOTIENT((_xlfn.TEXTBEFORE(B11,":")*$E$2+_xlfn.TEXTAFTER(B11,":"))/$D$2,$E$2)&":"&TEXT(MOD((_xlfn.TEXTBEFORE(B11,":")*$E$2+_xlfn.TEXTAFTER(B11,":"))/$D$2,$E$2),"00") -> 4:40 | R11: =_xlfn.TEXTBEFORE(Q11,":") -> 4 | S11: =_xlfn.TEXTAFTER(Q11,":") -> 40 | T11: =R11*60+S11 -> 280 | U11: =T12-T11 -> 18 | V11: =D11 -> 25:15 | W11: =_xlfn.TEXTBEFORE(V11,":") -> 25 | X11: =_xlfn.TEXTAFTER(V11,":") -> 15 | Y11: =W11*60+X11 -> 1515 | Z11: =IF(AND(Y11>$BR$8,SUM($Z$5:Z10)=0),1,0) -> 0 | AA11: =Y12-Y11 -> 105 | AB11: =IF(Z12=1,$BR$8-Y11,0) -> 0 | AC11: =AB11/AA11 -> 0 | AD11: =QUOTIENT((_xlfn.TEXTBEFORE(E11,":")*$E$2+_xlfn.TEXTAFTER(E11,":"))/$D$2,$E$2)&":"&TEXT(MOD((_xlfn.TEXTBEFORE(E11,":")*$E$2+_xlfn.TEXTAFTER(E11,":"))/$D$2,$E$2),"00") -> 5:01 | AE11: =_xlfn.TEXTBEFORE(AD11,":") -> 5 | AF11: =_xlfn.TEXTAFTER(AD11,":") -> 01 | AG11: =AE11*60+AF11 -> 301 | AH11: =AG12-AG11 -> 22 | AI11: =G11 -> 52:30 | AJ11: =QUOTIENT((_xlfn.TEXTBEFORE(H11,":")*$E$2+_xlfn.TEXTAFTER(H11,":"))/$D$2,$E$2)&":"&TEXT(MOD((_xlfn.TEXTBEFORE(H11,":")*$E$2+_xlfn.TEXTAFTER(H11,":"))/$D$2,$E$2),"00") -> 5:14 | AK11: =_xlfn.TEXTBEFORE(AJ11,":") -> 5 | AL11: =_xlfn.TEXTAFTER(AJ11,":") -> 14 | AM11: =AK11*60+AL11 -> 314 | AN11: =AM12-AM11 -> 22 | AO11: =QUOTIENT((_xlfn.TEXTBEFORE(I11,":")*$E$2+_xlfn.TEXTAFTER(I11,":"))/$D$2,$E$2)&":"&TEXT(MOD((_xlfn.TEXTBEFORE(I11,":")*$E$2+_xlfn.TEXTAFTER(I11,":"))/$D$2,$E$2),"00") -> 5:29 | AP11: =_xlfn.TEXTBEFORE(AO11,":") -> 5 | AQ11: =_xlfn.TEXTAFTER(AO11,":") -> 29 | AR11: =AP11*60+AQ11 -> 329 | AS11: =AR12-AR11 -> 22 | AT11: =K11 -> 1:55:00 | AU11: =QUOTIENT((_xlfn.TEXTBEFORE(L11,":")*$E$2+_xlfn.TEXTAFTER(L11,":"))/$D$2,$E$2)&":"&TEXT(MOD((_xlfn.TEXTBEFORE(L11,":")*$E$2+_xlfn.TEXTAFTER(L11,":"))/$D$2,$E$2),"00") -> 5:26 | AV11: =_xlfn.TEXTBEFORE(AU11,":") -> 5 | AW11: =_xlfn.TEXTAFTER(AU11,":") -> 26 | AX11: =AV11*60+AW11 -> 326 | AY11: =AX12-AX11 -> 28 | AZ11: =N11 -> 4:00:00 | BA11: =QUOTIENT((_xlfn.TEXTBEFORE(O11,":")*$E$2+_xlfn.TEXTAFTER(O11,":"))/$D$2,$E$2)&":"&TEXT(MOD((_xlfn.TEXTBEFORE(O11,":")*$E$2+_xlfn.TEXTAFTER(O11,":"))/$D$2,$E$2),"00") -> 5:42 | BB11: =_xlfn.TEXTBEFORE(BA11,":") -> 5 | BC11: =_xlfn.TEXTAFTER(BA11,":") -> 42 | BD11: =BB11*60+BC11 -> 342 | BE11: =BD12-BD11 -> 22 | BF11: =BB11*60+BC11 -> 342 | BG11: =QUOTIENT((_xlfn.TEXTBEFORE(P11,":")*$E$2+_xlfn.TEXTAFTER(P11,":"))/$D$2,$E$2)&":"&TEXT(MOD((_xlfn.TEXTBEFORE(P11,":")*$E$2+_xlfn.TEXTAFTER(P11,":"))/$D$2,$E$2),"00") -> 6:10 | BH11: =_xlfn.TEXTBEFORE(BG11,":") -> 6 | BI11: =_xlfn.TEXTAFTER(BG11,":") -> 10 | BJ11: =BH11*60+BI11 -> 370 | BK11: =BJ12-BJ11 -> 21 | BN11: 5k avg. | BO11: =TEXT(BP11,"00")&":"&TEXT(BQ11,"00") -> 04:37 | BP11: =QUOTIENT(BR11,$E$2) -> 4 | BQ11: =MOD(BR11,$E$2) -> 36.780952 | BR11: =BS11+BT11 -> 276.78095 | BS11: {=INDEX($AG$6:$AG$20,MATCH(1,$Z$6:$Z$20,0)-1)} -> 264 | BT11: =SUMPRODUCT($AH$6:$AH$19,$AC$6:$AC$19) -> 12.780952 | BU11: 5 | BV11: =ROUND(1/BR11*60*1000,-1) -> 220 | BW11: =3600/BR11 -> 13.006675 | BX11: =TIME(,,BR11*BU11) -> 0.016006944 | BY11: 5k
B12: 8:00 | C12: 27:00/8:40 | D12: 27:00 | E12: 8:40 | F12: 55:50/9:00 | G12: 55:50 | H12: 9:00 | I12: 9:25 | J12: 2:05:00/9:30 | K12: 2:05:00 | L12: 9:30 | M12: 4:15:00/9:45 | N12: 4:15:00 | O12: 9:45 | P12: 10:30 | Q12: =QUOTIENT((_xlfn.TEXTBEFORE(B12,":")*$E$2+_xlfn.TEXTAFTER(B12,":"))/$D$2,$E$2)&":"&TEXT(MOD((_xlfn.TEXTBEFORE(B12,":")*$E$2+_xlfn.TEXTAFTER(B12,":"))/$D$2,$E$2),"00") -> 4:58 | R12: =_xlfn.TEXTBEFORE(Q12,":") -> 4 | S12: =_xlfn.TEXTAFTER(Q12,":") -> 58 | T12: =R12*60+S12 -> 298 | U12: =T13-T12 -> 19 | V12: =D12 -> 27:00 | W12: =_xlfn.TEXTBEFORE(V12,":") -> 27 | X12: =_xlfn.TEXTAFTER(V12,":") -> 00 | Y12: =W12*60+X12 -> 1620 | Z12: =IF(AND(Y12>$BR$8,SUM($Z$5:Z11)=0),1,0) -> 0 | AA12: =Y13-Y12 -> 90 | AB12: =IF(Z13=1,$BR$8-Y12,0) -> 0 | AC12: =AB12/AA12 -> 0 | AD12: =QUOTIENT((_xlfn.TEXTBEFORE(E12,":")*$E$2+_xlfn.TEXTAFTER(E12,":"))/$D$2,$E$2)&":"&TEXT(MOD((_xlfn.TEXTBEFORE(E12,":")*$E$2+_xlfn.TEXTAFTER(E12,":"))/$D$2,$E$2),"00") -> 5:23 | AE12: =_xlfn.TEXTBEFORE(AD12,":") -> 5 | AF12: =_xlfn.TEXTAFTER(AD12,":") -> 23 | AG12: =AE12*60+AF12 -> 323 | AH12: =AG13-AG12 -> 19 | AI12: =G12 -> 55:50 | AJ12: =QUOTIENT((_xlfn.TEXTBEFORE(H12,":")*$E$2+_xlfn.TEXTAFTER(H12,":"))/$D$2,$E$2)&":"&TEXT(MOD((_xlfn.TEXTBEFORE(H12,":")*$E$2+_xlfn.TEXTAFTER(H12,":"))/$D$2,$E$2),"00") -> 5:36 | AK12: =_xlfn.TEXTBEFORE(AJ12,":") -> 5 | AL12: =_xlfn.TEXTAFTER(AJ12,":") -> 36 | AM12: =AK12*60+AL12 -> 336 | AN12: =AM13-AM12 -> 18 | AO12: =QUOTIENT((_xlfn.TEXTBEFORE(I12,":")*$E$2+_xlfn.TEXTAFTER(I12,":"))/$D$2,$E$2)&":"&TEXT(MOD((_xlfn.TEXTBEFORE(I12,":")*$E$2+_xlfn.TEXTAFTER(I12,":"))/$D$2,$E$2),"00") -> 5:51 | AP12: =_xlfn.TEXTBEFORE(AO12,":") -> 5 | AQ12: =_xlfn.TEXTAFTER(AO12,":") -> 51 | AR12: =AP12*60+AQ12 -> 351 | AS12: =AR13-AR12 -> 19 | AT12: =K12 -> 2:05:00 | AU12: =QUOTIENT((_xlfn.TEXTBEFORE(L12,":")*$E$2+_xlfn.TEXTAFTER(L12,":"))/$D$2,$E$2)&":"&TEXT(MOD((_xlfn.TEXTBEFORE(L12,":")*$E$2+_xlfn.TEXTAFTER(L12,":"))/$D$2,$E$2),"00") -> 5:54 | AV12: =_xlfn.TEXTBEFORE(AU12,":") -> 5 | AW12: =_xlfn.TEXTAFTER(AU12,":") -> 54 | AX12: =AV12*60+AW12 -> 354 | AY12: =AX13-AX12 -> 16 | AZ12: =N12 -> 4:15:00 | BA12: =QUOTIENT((_xlfn.TEXTBEFORE(O12,":")*$E$2+_xlfn.TEXTAFTER(O12,":"))/$D$2,$E$2)&":"&TEXT(MOD((_xlfn.TEXTBEFORE(O12,":")*$E$2+_xlfn.TEXTAFTER(O12,":"))/$D$2,$E$2),"00") -> 6:04 | BB12: =_xlfn.TEXTBEFORE(BA12,":") -> 6 | BC12: =_xlfn.TEXTAFTER(BA12,":") -> 04 | BD12: =BB12*60+BC12 -> 364 | BE12: =BD13-BD12 -> 18 | BF12: =BB12*60+BC12 -> 364 | BG12: =QUOTIENT((_xlfn.TEXTBEFORE(P12,":")*$E$2+_xlfn.TEXTAFTER(P12,":"))/$D$2,$E$2)&":"&TEXT(MOD((_xlfn.TEXTBEFORE(P12,":")*$E$2+_xlfn.TEXTAFTER(P12,":"))/$D$2,$E$2),"00") -> 6:31 | BH12: =_xlfn.TEXTBEFORE(BG12,":") -> 6 | BI12: =_xlfn.TEXTAFTER(BG12,":") -> 31 | BJ12: =BH12*60+BI12 -> 391 | BK12: =BJ13-BJ12 -> 19 | BN12: 10k avg. | BO12: =TEXT(BP12,"00")&":"&TEXT(BQ12,"00") -> 04:46 | BP12: =QUOTIENT(BR12,$E$2) -> 4 | BQ12: =MOD(BR12,$E$2) -> 45.780952 | BR12: =BS12+BT12 -> 285.78095 | BS12: {=INDEX($AM$6:$AM$20,MATCH(1,$Z$6:$Z$20,0)-1)} -> 273 | BT12: =SUMPRODUCT($AN$6:$AN$19,$AC$6:$AC$19) -> 12.780952 | BU12: 10 | BV12: =ROUND(1/BR12*60*1000,-1) -> 210 | BW12: =3600/BR12 -> 12.597061 | BX12: =TIME(,,BR12*BU12) -> 0.03306713 | BY12: 10k
B13: 8:30 | C13: 28:30/9:10 | D13: 28:30 | E13: 9:10 | F13: 59:00/9:30 | G13: 59:00 | H13: 9:30 | I13: 9:55 | J13: 2:10:00/9:55 | K13: 2:10:00 | L13: 9:55 | M13: 4:30:00/10:15 | N13: 4:30:00 | O13: 10:15 | P13: 11:00 | Q13: =QUOTIENT((_xlfn.TEXTBEFORE(B13,":")*$E$2+_xlfn.TEXTAFTER(B13,":"))/$D$2,$E$2)&":"&TEXT(MOD((_xlfn.TEXTBEFORE(B13,":")*$E$2+_xlfn.TEXTAFTER(B13,":"))/$D$2,$E$2),"00") -> 5:17 | R13: =_xlfn.TEXTBEFORE(Q13,":") -> 5 | S13: =_xlfn.TEXTAFTER(Q13,":") -> 17 | T13: =R13*60+S13 -> 317 | U13: =T14-T13 -> 19 | V13: =D13 -> 28:30 | W13: =_xlfn.TEXTBEFORE(V13,":") -> 28 | X13: =_xlfn.TEXTAFTER(V13,":") -> 30 | Y13: =W13*60+X13 -> 1710 | Z13: =IF(AND(Y13>$BR$8,SUM($Z$5:Z12)=0),1,0) -> 0 | AA13: =Y14-Y13 -> 90 | AB13: =IF(Z14=1,$BR$8-Y13,0) -> 0 | AC13: =AB13/AA13 -> 0 | AD13: =QUOTIENT((_xlfn.TEXTBEFORE(E13,":")*$E$2+_xlfn.TEXTAFTER(E13,":"))/$D$2,$E$2)&":"&TEXT(MOD((_xlfn.TEXTBEFORE(E13,":")*$E$2+_xlfn.TEXTAFTER(E13,":"))/$D$2,$E$2),"00") -> 5:42 | AE13: =_xlfn.TEXTBEFORE(AD13,":") -> 5 | AF13: =_xlfn.TEXTAFTER(AD13,":") -> 42 | AG13: =AE13*60+AF13 -> 342 | AH13: =AG14-AG13 -> 18 | AI13: =G13 -> 59:00 | AJ13: =QUOTIENT((_xlfn.TEXTBEFORE(H13,":")*$E$2+_xlfn.TEXTAFTER(H13,":"))/$D$2,$E$2)&":"&TEXT(MOD((_xlfn.TEXTBEFORE(H13,":")*$E$2+_xlfn.TEXTAFTER(H13,":"))/$D$2,$E$2),"00") -> 5:54 | AK13: =_xlfn.TEXTBEFORE(AJ13,":") -> 5 | AL13: =_xlfn.TEXTAFTER(AJ13,":") -> 54 | AM13: =AK13*60+AL13 -> 354 | AN13: =AM14-AM13 -> 19 | AO13: =QUOTIENT((_xlfn.TEXTBEFORE(I13,":")*$E$2+_xlfn.TEXTAFTER(I13,":"))/$D$2,$E$2)&":"&TEXT(MOD((_xlfn.TEXTBEFORE(I13,":")*$E$2+_xlfn.TEXTAFTER(I13,":"))/$D$2,$E$2),"00") -> 6:10 | AP13: =_xlfn.TEXTBEFORE(AO13,":") -> 6 | AQ13: =_xlfn.TEXTAFTER(AO13,":") -> 10 | AR13: =AP13*60+AQ13 -> 370 | AS13: =AR14-AR13 -> 21 | AT13: =K13 -> 2:10:00 | AU13: =QUOTIENT((_xlfn.TEXTBEFORE(L13,":")*$E$2+_xlfn.TEXTAFTER(L13,":"))/$D$2,$E$2)&":"&TEXT(MOD((_xlfn.TEXTBEFORE(L13,":")*$E$2+_xlfn.TEXTAFTER(L13,":"))/$D$2,$E$2),"00") -> 6:10 | AV13: =_xlfn.TEXTBEFORE(AU13,":") -> 6 | AW13: =_xlfn.TEXTAFTER(AU13,":") -> 10 | AX13: =AV13*60+AW13 -> 370 | AY13: =AX14-AX13 -> 28 | AZ13: =N13 -> 4:30:00 | BA13: =QUOTIENT((_xlfn.TEXTBEFORE(O13,":")*$E$2+_xlfn.TEXTAFTER(O13,":"))/$D$2,$E$2)&":"&TEXT(MOD((_xlfn.TEXTBEFORE(O13,":")*$E$2+_xlfn.TEXTAFTER(O13,":"))/$D$2,$E$2),"00") -> 6:22 | BB13: =_xlfn.TEXTBEFORE(BA13,":") -> 6 | BC13: =_xlfn.TEXTAFTER(BA13,":") -> 22 | BD13: =BB13*60+BC13 -> 382 | BE13: =BD14-BD13 -> 22 | BF13: =BB13*60+BC13 -> 382 | BG13: =QUOTIENT((_xlfn.TEXTBEFORE(P13,":")*$E$2+_xlfn.TEXTAFTER(P13,":"))/$D$2,$E$2)&":"&TEXT(MOD((_xlfn.TEXTBEFORE(P13,":")*$E$2+_xlfn.TEXTAFTER(P13,":"))/$D$2,$E$2),"00") -> 6:50 | BH13: =_xlfn.TEXTBEFORE(BG13,":") -> 6 | BI13: =_xlfn.TEXTAFTER(BG13,":") -> 50 | BJ13: =BH13*60+BI13 -> 410 | BK13: =BJ14-BJ13 -> 22 | BN13: Tempo | BO13: =TEXT(BP13,"00")&":"&TEXT(BQ13,"00") -> 04:59 | BP13: =QUOTIENT(BR13,$E$2) -> 4 | BQ13: =MOD(BR13,$E$2) -> 58.780952 | BR13: =BS13+BT13 -> 298.78095 | BS13: {=INDEX($AR$6:$AR$20,MATCH(1,$Z$6:$Z$20,0)-1)} -> 286 | BT13: =SUMPRODUCT($AS$6:$AS$19,$AC$6:$AC$19) -> 12.780952 | BV13: =ROUND(1/BR13*60*1000,-1) -> 200 | BW13: =3600/BR13 -> 12.048961 | BY13: Tempo
B14: 9:00 | C14: 30:00/9:40 | D14: 30:00 | E14: 9:40 | F14: 62:30/10:00 | G14: 62:30 | H14: 10:00 | I14: 10:30 | J14: 2:20:00/10:40 | K14: 2:20:00 | L14: 10:40 | M14: 4:45:00/10:50 | N14: 4:45:00 | O14: 10:50 | P14: 11:35 | Q14: =QUOTIENT((_xlfn.TEXTBEFORE(B14,":")*$E$2+_xlfn.TEXTAFTER(B14,":"))/$D$2,$E$2)&":"&TEXT(MOD((_xlfn.TEXTBEFORE(B14,":")*$E$2+_xlfn.TEXTAFTER(B14,":"))/$D$2,$E$2),"00") -> 5:36 | R14: =_xlfn.TEXTBEFORE(Q14,":") -> 5 | S14: =_xlfn.TEXTAFTER(Q14,":") -> 36 | T14: =R14*60+S14 -> 336 | U14: =T15-T14 -> 18 | V14: =D14 -> 30:00 | W14: =_xlfn.TEXTBEFORE(V14,":") -> 30 | X14: =_xlfn.TEXTAFTER(V14,":") -> 00 | Y14: =W14*60+X14 -> 1800 | Z14: =IF(AND(Y14>$BR$8,SUM($Z$5:Z13)=0),1,0) -> 0 | AA14: =Y15-Y14 -> 105 | AB14: =IF(Z15=1,$BR$8-Y14,0) -> 0 | AC14: =AB14/AA14 -> 0 | AD14: =QUOTIENT((_xlfn.TEXTBEFORE(E14,":")*$E$2+_xlfn.TEXTAFTER(E14,":"))/$D$2,$E$2)&":"&TEXT(MOD((_xlfn.TEXTBEFORE(E14,":")*$E$2+_xlfn.TEXTAFTER(E14,":"))/$D$2,$E$2),"00") -> 6:00 | AE14: =_xlfn.TEXTBEFORE(AD14,":") -> 6 | AF14: =_xlfn.TEXTAFTER(AD14,":") -> 00 | AG14: =AE14*60+AF14 -> 360 | AH14: =AG15-AG14 -> 22 | AI14: =G14 -> 62:30 | AJ14: =QUOTIENT((_xlfn.TEXTBEFORE(H14,":")*$E$2+_xlfn.TEXTAFTER(H14,":"))/$D$2,$E$2)&":"&TEXT(MOD((_xlfn.TEXTBEFORE(H14,":")*$E$2+_xlfn.TEXTAFTER(H14,":"))/$D$2,$E$2),"00") -> 6:13 | AK14: =_xlfn.TEXTBEFORE(AJ14,":") -> 6 | AL14: =_xlfn.TEXTAFTER(AJ14,":") -> 13 | AM14: =AK14*60+AL14 -> 373 | AN14: =AM15-AM14 -> 22 | AO14: =QUOTIENT((_xlfn.TEXTBEFORE(I14,":")*$E$2+_xlfn.TEXTAFTER(I14,":"))/$D$2,$E$2)&":"&TEXT(MOD((_xlfn.TEXTBEFORE(I14,":")*$E$2+_xlfn.TEXTAFTER(I14,":"))/$D$2,$E$2),"00") -> 6:31 | AP14: =_xlfn.TEXTBEFORE(AO14,":") -> 6 | AQ14: =_xlfn.TEXTAFTER(AO14,":") -> 31 | AR14: =AP14*60+AQ14 -> 391 | AS14: =AR15-AR14 -> 19 | AT14: =K14 -> 2:20:00 | AU14: =QUOTIENT((_xlfn.TEXTBEFORE(L14,":")*$E$2+_xlfn.TEXTAFTER(L14,":"))/$D$2,$E$2)&":"&TEXT(MOD((_xlfn.TEXTBEFORE(L14,":")*$E$2+_xlfn.TEXTAFTER(L14,":"))/$D$2,$E$2),"00") -> 6:38 | AV14: =_xlfn.TEXTBEFORE(AU14,":") -> 6 | AW14: =_xlfn.TEXTAFTER(AU14,":") -> 38 | AX14: =AV14*60+AW14 -> 398 | AY14: =AX15-AX14 -> 15 | AZ14: =N14 -> 4:45:00 | BA14: =QUOTIENT((_xlfn.TEXTBEFORE(O14,":")*$E$2+_xlfn.TEXTAFTER(O14,":"))/$D$2,$E$2)&":"&TEXT(MOD((_xlfn.TEXTBEFORE(O14,":")*$E$2+_xlfn.TEXTAFTER(O14,":"))/$D$2,$E$2),"00") -> 6:44 | BB14: =_xlfn.TEXTBEFORE(BA14,":") -> 6 | BC14: =_xlfn.TEXTAFTER(BA14,":") -> 44 | BD14: =BB14*60+BC14 -> 404 | BE14: =BD15-BD14 -> 22 | BF14: =BB14*60+BC14 -> 404 | BG14: =QUOTIENT((_xlfn.TEXTBEFORE(P14,":")*$E$2+_xlfn.TEXTAFTER(P14,":"))/$D$2,$E$2)&":"&TEXT(MOD((_xlfn.TEXTBEFORE(P14,":")*$E$2+_xlfn.TEXTAFTER(P14,":"))/$D$2,$E$2),"00") -> 7:12 | BH14: =_xlfn.TEXTBEFORE(BG14,":") -> 7 | BI14: =_xlfn.TEXTAFTER(BG14,":") -> 12 | BJ14: =BH14*60+BI14 -> 432 | BK14: =BJ15-BJ14 -> 22 | BN14: Half avg. | BO14: =TEXT(BP14,"00")&":"&TEXT(BQ14,"00") -> 04:59 | BP14: =QUOTIENT(BR14,$E$2) -> 4 | BQ14: =MOD(BR14,$E$2) -> 59.266667 | BR14: =BS14+BT14 -> 299.26667 | BS14: {=INDEX($AX$6:$AX$20,MATCH(1,$Z$6:$Z$20,0)-1)} -> 283 | BT14: =SUMPRODUCT($AY$6:$AY$19,$AC$6:$AC$19) -> 16.266667 | BU14: 21.1 | BV14: =ROUND(1/BR14*60*1000,-1) -> 200 | BW14: =3600/BR14 -> 12.029405 | BX14: =TIME(,,BR14*BU14) -> 0.073078704 | BY14: Half
B15: 9:30 | C15: 31:45/10:15 | D15: 31:45 | E15: 10:15 | F15: 66:00/10:35 | G15: 66:00 | H15: 10:35 | I15: 11:00 | J15: 2:25:00/11:05 | K15: 2:25:00 | L15: 11:05 | M15: 5:00:00/11:25 | N15: 5:00:00 | O15: 11:25 | P15: 12:10 | Q15: =QUOTIENT((_xlfn.TEXTBEFORE(B15,":")*$E$2+_xlfn.TEXTAFTER(B15,":"))/$D$2,$E$2)&":"&TEXT(MOD((_xlfn.TEXTBEFORE(B15,":")*$E$2+_xlfn.TEXTAFTER(B15,":"))/$D$2,$E$2),"00") -> 5:54 | R15: =_xlfn.TEXTBEFORE(Q15,":") -> 5 | S15: =_xlfn.TEXTAFTER(Q15,":") -> 54 | T15: =R15*60+S15 -> 354 | U15: =T16-T15 -> 19 | V15: =D15 -> 31:45 | W15: =_xlfn.TEXTBEFORE(V15,":") -> 31 | X15: =_xlfn.TEXTAFTER(V15,":") -> 45 | Y15: =W15*60+X15 -> 1905 | Z15: =IF(AND(Y15>$BR$8,SUM($Z$5:Z14)=0),1,0) -> 0 | AA15: =Y16-Y15 -> 75 | AB15: =IF(Z16=1,$BR$8-Y15,0) -> 0 | AC15: =AB15/AA15 -> 0 | AD15: =QUOTIENT((_xlfn.TEXTBEFORE(E15,":")*$E$2+_xlfn.TEXTAFTER(E15,":"))/$D$2,$E$2)&":"&TEXT(MOD((_xlfn.TEXTBEFORE(E15,":")*$E$2+_xlfn.TEXTAFTER(E15,":"))/$D$2,$E$2),"00") -> 6:22 | AE15: =_xlfn.TEXTBEFORE(AD15,":") -> 6 | AF15: =_xlfn.TEXTAFTER(AD15,":") -> 22 | AG15: =AE15*60+AF15 -> 382 | AH15: =AG16-AG15 -> 16 | AI15: =G15 -> 66:00 | AJ15: =QUOTIENT((_xlfn.TEXTBEFORE(H15,":")*$E$2+_xlfn.TEXTAFTER(H15,":"))/$D$2,$E$2)&":"&TEXT(MOD((_xlfn.TEXTBEFORE(H15,":")*$E$2+_xlfn.TEXTAFTER(H15,":"))/$D$2,$E$2),"00") -> 6:35 | AK15: =_xlfn.TEXTBEFORE(AJ15,":") -> 6 | AL15: =_xlfn.TEXTAFTER(AJ15,":") -> 35 | AM15: =AK15*60+AL15 -> 395 | AN15: =AM16-AM15 -> 18 | AO15: =QUOTIENT((_xlfn.TEXTBEFORE(I15,":")*$E$2+_xlfn.TEXTAFTER(I15,":"))/$D$2,$E$2)&":"&TEXT(MOD((_xlfn.TEXTBEFORE(I15,":")*$E$2+_xlfn.TEXTAFTER(I15,":"))/$D$2,$E$2),"00") -> 6:50 | AP15: =_xlfn.TEXTBEFORE(AO15,":") -> 6 | AQ15: =_xlfn.TEXTAFTER(AO15,":") -> 50 | AR15: =AP15*60+AQ15 -> 410 | AS15: =AR16-AR15 -> 22 | AT15: =K15 -> 2:25:00 | AU15: =QUOTIENT((_xlfn.TEXTBEFORE(L15,":")*$E$2+_xlfn.TEXTAFTER(L15,":"))/$D$2,$E$2)&":"&TEXT(MOD((_xlfn.TEXTBEFORE(L15,":")*$E$2+_xlfn.TEXTAFTER(L15,":"))/$D$2,$E$2),"00") -> 6:53 | AV15: =_xlfn.TEXTBEFORE(AU15,":") -> 6 | AW15: =_xlfn.TEXTAFTER(AU15,":") -> 53 | AX15: =AV15*60+AW15 -> 413 | AY15: =AX16-AX15 -> 25 | AZ15: =N15 -> 5:00:00 | BA15: =QUOTIENT((_xlfn.TEXTBEFORE(O15,":")*$E$2+_xlfn.TEXTAFTER(O15,":"))/$D$2,$E$2)&":"&TEXT(MOD((_xlfn.TEXTBEFORE(O15,":")*$E$2+_xlfn.TEXTAFTER(O15,":"))/$D$2,$E$2),"00") -> 7:06 | BB15: =_xlfn.TEXTBEFORE(BA15,":") -> 7 | BC15: =_xlfn.TEXTAFTER(BA15,":") -> 06 | BD15: =BB15*60+BC15 -> 426 | BE15: =BD16-BD15 -> 21 | BF15: =BB15*60+BC15 -> 426 | BG15: =QUOTIENT((_xlfn.TEXTBEFORE(P15,":")*$E$2+_xlfn.TEXTAFTER(P15,":"))/$D$2,$E$2)&":"&TEXT(MOD((_xlfn.TEXTBEFORE(P15,":")*$E$2+_xlfn.TEXTAFTER(P15,":"))/$D$2,$E$2),"00") -> 7:34 | BH15: =_xlfn.TEXTBEFORE(BG15,":") -> 7 | BI15: =_xlfn.TEXTAFTER(BG15,":") -> 34 | BJ15: =BH15*60+BI15 -> 454 | BK15: =BJ16-BJ15 -> 21 | BN15: Full avg. | BO15: =TEXT(BP15,"00")&":"&TEXT(BQ15,"00") -> 05:11 | BP15: =QUOTIENT(BR15,$E$2) -> 5 | BQ15: =MOD(BR15,$E$2) -> 10.780952 | BR15: =BS15+BT15 -> 310.78095 | BS15: {=INDEX($BD$6:$BD$20,MATCH(1,$Z$6:$Z$20,0)-1)} -> 298 | BT15: =SUMPRODUCT($BE$6:$BE$19,$AC$6:$AC$19) -> 12.780952 | BU15: 42.195 | BV15: =ROUND(1/BR15*60*1000,-1) -> 190 | BW15: =3600/BR15 -> 11.583722 | BX15: =TIME(,,BR15*BU15) -> 0.15177083 | BY15: Full
B16: 10:00 | C16: 33:00/10:40 | D16: 33:00 | E16: 10:40 | F16: 69:00/11:05 | G16: 69:00 | H16: 11:05 | I16: 11:35 | J16: 2:35:00/11:45 | K16: 2:35:00 | L16: 11:45 | M16: 5:15:00/12:00 | N16: 5:15:00 | O16: 12:00 | P16: 12:45 | Q16: =QUOTIENT((_xlfn.TEXTBEFORE(B16,":")*$E$2+_xlfn.TEXTAFTER(B16,":"))/$D$2,$E$2)&":"&TEXT(MOD((_xlfn.TEXTBEFORE(B16,":")*$E$2+_xlfn.TEXTAFTER(B16,":"))/$D$2,$E$2),"00") -> 6:13 | R16: =_xlfn.TEXTBEFORE(Q16,":") -> 6 | S16: =_xlfn.TEXTAFTER(Q16,":") -> 13 | T16: =R16*60+S16 -> 373 | U16: =T17-T16 -> 18 | V16: =D16 -> 33:00 | W16: =_xlfn.TEXTBEFORE(V16,":") -> 33 | X16: =_xlfn.TEXTAFTER(V16,":") -> 00 | Y16: =W16*60+X16 -> 1980 | Z16: =IF(AND(Y16>$BR$8,SUM($Z$5:Z15)=0),1,0) -> 0 | AA16: =Y17-Y16 -> 120 | AB16: =IF(Z17=1,$BR$8-Y16,0) -> 0 | AC16: =AB16/AA16 -> 0 | AD16: =QUOTIENT((_xlfn.TEXTBEFORE(E16,":")*$E$2+_xlfn.TEXTAFTER(E16,":"))/$D$2,$E$2)&":"&TEXT(MOD((_xlfn.TEXTBEFORE(E16,":")*$E$2+_xlfn.TEXTAFTER(E16,":"))/$D$2,$E$2),"00") -> 6:38 | AE16: =_xlfn.TEXTBEFORE(AD16,":") -> 6 | AF16: =_xlfn.TEXTAFTER(AD16,":") -> 38 | AG16: =AE16*60+AF16 -> 398 | AH16: =AG17-AG16 -> 21 | AI16: =G16 -> 69:00 | AJ16: =QUOTIENT((_xlfn.TEXTBEFORE(H16,":")*$E$2+_xlfn.TEXTAFTER(H16,":"))/$D$2,$E$2)&":"&TEXT(MOD((_xlfn.TEXTBEFORE(H16,":")*$E$2+_xlfn.TEXTAFTER(H16,":"))/$D$2,$E$2),"00") -> 6:53 | AK16: =_xlfn.TEXTBEFORE(AJ16,":") -> 6 | AL16: =_xlfn.TEXTAFTER(AJ16,":") -> 53 | AM16: =AK16*60+AL16 -> 413 | AN16: =AM17-AM16 -> 19 | AO16: =QUOTIENT((_xlfn.TEXTBEFORE(I16,":")*$E$2+_xlfn.TEXTAFTER(I16,":"))/$D$2,$E$2)&":"&TEXT(MOD((_xlfn.TEXTBEFORE(I16,":")*$E$2+_xlfn.TEXTAFTER(I16,":"))/$D$2,$E$2),"00") -> 7:12 | AP16: =_xlfn.TEXTBEFORE(AO16,":") -> 7 | AQ16: =_xlfn.TEXTAFTER(AO16,":") -> 12 | AR16: =AP16*60+AQ16 -> 432 | AS16: =AR17-AR16 -> 15 | AT16: =K16 -> 2:35:00 | AU16: =QUOTIENT((_xlfn.TEXTBEFORE(L16,":")*$E$2+_xlfn.TEXTAFTER(L16,":"))/$D$2,$E$2)&":"&TEXT(MOD((_xlfn.TEXTBEFORE(L16,":")*$E$2+_xlfn.TEXTAFTER(L16,":"))/$D$2,$E$2),"00") -> 7:18 | AV16: =_xlfn.TEXTBEFORE(AU16,":") -> 7 | AW16: =_xlfn.TEXTAFTER(AU16,":") -> 18 | AX16: =AV16*60+AW16 -> 438 | AY16: =AX17-AX16 -> 16 | AZ16: =N16 -> 5:15:00 | BA16: =QUOTIENT((_xlfn.TEXTBEFORE(O16,":")*$E$2+_xlfn.TEXTAFTER(O16,":"))/$D$2,$E$2)&":"&TEXT(MOD((_xlfn.TEXTBEFORE(O16,":")*$E$2+_xlfn.TEXTAFTER(O16,":"))/$D$2,$E$2),"00") -> 7:27 | BB16: =_xlfn.TEXTBEFORE(BA16,":") -> 7 | BC16: =_xlfn.TEXTAFTER(BA16,":") -> 27 | BD16: =BB16*60+BC16 -> 447 | BE16: =BD17-BD16 -> 22 | BF16: =BB16*60+BC16 -> 447 | BG16: =QUOTIENT((_xlfn.TEXTBEFORE(P16,":")*$E$2+_xlfn.TEXTAFTER(P16,":"))/$D$2,$E$2)&":"&TEXT(MOD((_xlfn.TEXTBEFORE(P16,":")*$E$2+_xlfn.TEXTAFTER(P16,":"))/$D$2,$E$2),"00") -> 7:55 | BH16: =_xlfn.TEXTBEFORE(BG16,":") -> 7 | BI16: =_xlfn.TEXTAFTER(BG16,":") -> 55 | BJ16: =BH16*60+BI16 -> 475 | BK16: =BJ17-BJ16 -> 22 | BN16: Recovery | BO16: =TEXT(BP16,"00")&":"&TEXT(BQ16,"00") -> 05:39 | BP16: =QUOTIENT(BR16,$E$2) -> 5 | BQ16: =MOD(BR16,$E$2) -> 38.780952 | BR16: =BS16+BT16 -> 338.78095 | BS16: {=INDEX($BJ$6:$BJ$20,MATCH(1,$Z$6:$Z$20,0)-1)} -> 326 | BT16: =SUMPRODUCT($BK$6:$BK$19,$AC$6:$AC$19) -> 12.780952 | BV16: =ROUND(1/BR16*60*1000,-1) -> 180 | BW16: =3600/BR16 -> 10.626335 | BY16: Recovery
B17: 10:30 | C17: 35:00/11:15 | D17: 35:00 | E17: 11:15 | F17: 72:00/11:35 | G17: 72:00 | H17: 11:35 | I17: 12:00 | J17: 2:40:00/12:10 | K17: 2:40:00 | L17: 12:10 | M17: 5:30:00/12:35 | N17: 5:30:00 | O17: 12:35 | P17: 13:20 | Q17: =QUOTIENT((_xlfn.TEXTBEFORE(B17,":")*$E$2+_xlfn.TEXTAFTER(B17,":"))/$D$2,$E$2)&":"&TEXT(MOD((_xlfn.TEXTBEFORE(B17,":")*$E$2+_xlfn.TEXTAFTER(B17,":"))/$D$2,$E$2),"00") -> 6:31 | R17: =_xlfn.TEXTBEFORE(Q17,":") -> 6 | S17: =_xlfn.TEXTAFTER(Q17,":") -> 31 | T17: =R17*60+S17 -> 391 | U17: =T18-T17 -> 19 | V17: =D17 -> 35:00 | W17: =_xlfn.TEXTBEFORE(V17,":") -> 35 | X17: =_xlfn.TEXTAFTER(V17,":") -> 00 | Y17: =W17*60+X17 -> 2100 | Z17: =IF(AND(Y17>$BR$8,SUM($Z$5:Z16)=0),1,0) -> 0 | AA17: =Y18-Y17 -> 75 | AB17: =IF(Z18=1,$BR$8-Y17,0) -> 0 | AC17: =AB17/AA17 -> 0 | AD17: =QUOTIENT((_xlfn.TEXTBEFORE(E17,":")*$E$2+_xlfn.TEXTAFTER(E17,":"))/$D$2,$E$2)&":"&TEXT(MOD((_xlfn.TEXTBEFORE(E17,":")*$E$2+_xlfn.TEXTAFTER(E17,":"))/$D$2,$E$2),"00") -> 6:59 | AE17: =_xlfn.TEXTBEFORE(AD17,":") -> 6 | AF17: =_xlfn.TEXTAFTER(AD17,":") -> 59 | AG17: =AE17*60+AF17 -> 419 | AH17: =AG18-AG17 -> 16 | AI17: =G17 -> 72:00 | AJ17: =QUOTIENT((_xlfn.TEXTBEFORE(H17,":")*$E$2+_xlfn.TEXTAFTER(H17,":"))/$D$2,$E$2)&":"&TEXT(MOD((_xlfn.TEXTBEFORE(H17,":")*$E$2+_xlfn.TEXTAFTER(H17,":"))/$D$2,$E$2),"00") -> 7:12 | AK17: =_xlfn.TEXTBEFORE(AJ17,":") -> 7 | AL17: =_xlfn.TEXTAFTER(AJ17,":") -> 12 | AM17: =AK17*60+AL17 -> 432 | AN17: =AM18-AM17 -> 15 | AO17: =QUOTIENT((_xlfn.TEXTBEFORE(I17,":")*$E$2+_xlfn.TEXTAFTER(I17,":"))/$D$2,$E$2)&":"&TEXT(MOD((_xlfn.TEXTBEFORE(I17,":")*$E$2+_xlfn.TEXTAFTER(I17,":"))/$D$2,$E$2),"00") -> 7:27 | AP17: =_xlfn.TEXTBEFORE(AO17,":") -> 7 | AQ17: =_xlfn.TEXTAFTER(AO17,":") -> 27 | AR17: =AP17*60+AQ17 -> 447 | AS17: =AR18-AR17 -> 22 | AT17: =K17 -> 2:40:00 | AU17: =QUOTIENT((_xlfn.TEXTBEFORE(L17,":")*$E$2+_xlfn.TEXTAFTER(L17,":"))/$D$2,$E$2)&":"&TEXT(MOD((_xlfn.TEXTBEFORE(L17,":")*$E$2+_xlfn.TEXTAFTER(L17,":"))/$D$2,$E$2),"00") -> 7:34 | AV17: =_xlfn.TEXTBEFORE(AU17,":") -> 7 | AW17: =_xlfn.TEXTAFTER(AU17,":") -> 34 | AX17: =AV17*60+AW17 -> 454 | AY17: =AX18-AX17 -> 28 | AZ17: =N17 -> 5:30:00 | BA17: =QUOTIENT((_xlfn.TEXTBEFORE(O17,":")*$E$2+_xlfn.TEXTAFTER(O17,":"))/$D$2,$E$2)&":"&TEXT(MOD((_xlfn.TEXTBEFORE(O17,":")*$E$2+_xlfn.TEXTAFTER(O17,":"))/$D$2,$E$2),"00") -> 7:49 | BB17: =_xlfn.TEXTBEFORE(BA17,":") -> 7 | BC17: =_xlfn.TEXTAFTER(BA17,":") -> 49 | BD17: =BB17*60+BC17 -> 469 | BE17: =BD18-BD17 -> 16 | BF17: =BB17*60+BC17 -> 469 | BG17: =QUOTIENT((_xlfn.TEXTBEFORE(P17,":")*$E$2+_xlfn.TEXTAFTER(P17,":"))/$D$2,$E$2)&":"&TEXT(MOD((_xlfn.TEXTBEFORE(P17,":")*$E$2+_xlfn.TEXTAFTER(P17,":"))/$D$2,$E$2),"00") -> 8:17 | BH17: =_xlfn.TEXTBEFORE(BG17,":") -> 8 | BI17: =_xlfn.TEXTAFTER(BG17,":") -> 17 | BJ17: =BH17*60+BI17 -> 497 | BK17: =BJ18-BJ17 -> 16
B18: 11:00 | C18: 36:15/11:40 | D18: 36:15 | E18: 11:40 | F18: 75:00/12:00 | G18: 75:00 | H18: 12:00 | I18: 12:35 | J18: 2:50:00/12:55 | K18: 2:50:00 | L18: 12:55 | M18: 5:40:00/13:00 | N18: 5:40:00 | O18: 13:00 | P18: 13:45 | Q18: =QUOTIENT((_xlfn.TEXTBEFORE(B18,":")*$E$2+_xlfn.TEXTAFTER(B18,":"))/$D$2,$E$2)&":"&TEXT(MOD((_xlfn.TEXTBEFORE(B18,":")*$E$2+_xlfn.TEXTAFTER(B18,":"))/$D$2,$E$2),"00") -> 6:50 | R18: =_xlfn.TEXTBEFORE(Q18,":") -> 6 | S18: =_xlfn.TEXTAFTER(Q18,":") -> 50 | T18: =R18*60+S18 -> 410 | U18: =T19-T18 -> 19 | V18: =D18 -> 36:15 | W18: =_xlfn.TEXTBEFORE(V18,":") -> 36 | X18: =_xlfn.TEXTAFTER(V18,":") -> 15 | Y18: =W18*60+X18 -> 2175 | Z18: =IF(AND(Y18>$BR$8,SUM($Z$5:Z17)=0),1,0) -> 0 | AA18: =Y19-Y18 -> 105 | AB18: =IF(Z19=1,$BR$8-Y18,0) -> 0 | AC18: =AB18/AA18 -> 0 | AD18: =QUOTIENT((_xlfn.TEXTBEFORE(E18,":")*$E$2+_xlfn.TEXTAFTER(E18,":"))/$D$2,$E$2)&":"&TEXT(MOD((_xlfn.TEXTBEFORE(E18,":")*$E$2+_xlfn.TEXTAFTER(E18,":"))/$D$2,$E$2),"00") -> 7:15 | AE18: =_xlfn.TEXTBEFORE(AD18,":") -> 7 | AF18: =_xlfn.TEXTAFTER(AD18,":") -> 15 | AG18: =AE18*60+AF18 -> 435 | AH18: =AG19-AG18 -> 22 | AI18: =G18 -> 75:00 | AJ18: =QUOTIENT((_xlfn.TEXTBEFORE(H18,":")*$E$2+_xlfn.TEXTAFTER(H18,":"))/$D$2,$E$2)&":"&TEXT(MOD((_xlfn.TEXTBEFORE(H18,":")*$E$2+_xlfn.TEXTAFTER(H18,":"))/$D$2,$E$2),"00") -> 7:27 | AK18: =_xlfn.TEXTBEFORE(AJ18,":") -> 7 | AL18: =_xlfn.TEXTAFTER(AJ18,":") -> 27 | AM18: =AK18*60+AL18 -> 447 | AN18: =AM19-AM18 -> 22 | AO18: =QUOTIENT((_xlfn.TEXTBEFORE(I18,":")*$E$2+_xlfn.TEXTAFTER(I18,":"))/$D$2,$E$2)&":"&TEXT(MOD((_xlfn.TEXTBEFORE(I18,":")*$E$2+_xlfn.TEXTAFTER(I18,":"))/$D$2,$E$2),"00") -> 7:49 | AP18: =_xlfn.TEXTBEFORE(AO18,":") -> 7 | AQ18: =_xlfn.TEXTAFTER(AO18,":") -> 49 | AR18: =AP18*60+AQ18 -> 469 | AS18: =AR19-AR18 -> 16 | AT18: =K18 -> 2:50:00 | AU18: =QUOTIENT((_xlfn.TEXTBEFORE(L18,":")*$E$2+_xlfn.TEXTAFTER(L18,":"))/$D$2,$E$2)&":"&TEXT(MOD((_xlfn.TEXTBEFORE(L18,":")*$E$2+_xlfn.TEXTAFTER(L18,":"))/$D$2,$E$2),"00") -> 8:02 | AV18: =_xlfn.TEXTBEFORE(AU18,":") -> 8 | AW18: =_xlfn.TEXTAFTER(AU18,":") -> 02 | AX18: =AV18*60+AW18 -> 482 | AY18: =AX19-AX18 -> 12 | AZ18: =N18 -> 5:40:00 | BA18: =QUOTIENT((_xlfn.TEXTBEFORE(O18,":")*$E$2+_xlfn.TEXTAFTER(O18,":"))/$D$2,$E$2)&":"&TEXT(MOD((_xlfn.TEXTBEFORE(O18,":")*$E$2+_xlfn.TEXTAFTER(O18,":"))/$D$2,$E$2),"00") -> 8:05 | BB18: =_xlfn.TEXTBEFORE(BA18,":") -> 8 | BC18: =_xlfn.TEXTAFTER(BA18,":") -> 05 | BD18: =BB18*60+BC18 -> 485 | BE18: =BD19-BD18 -> 12 | BF18: =BB18*60+BC18 -> 485 | BG18: =QUOTIENT((_xlfn.TEXTBEFORE(P18,":")*$E$2+_xlfn.TEXTAFTER(P18,":"))/$D$2,$E$2)&":"&TEXT(MOD((_xlfn.TEXTBEFORE(P18,":")*$E$2+_xlfn.TEXTAFTER(P18,":"))/$D$2,$E$2),"00") -> 8:33 | BH18: =_xlfn.TEXTBEFORE(BG18,":") -> 8 | BI18: =_xlfn.TEXTAFTER(BG18,":") -> 33 | BJ18: =BH18*60+BI18 -> 513 | BK18: =BJ19-BJ18 -> 12
B19: 11:30 | C19: 38:00/12:15 | D19: 38:00 | E19: 12:15 | F19: 78:30/12:35 | G19: 78:30 | H19: 12:35 | I19: 13:00 | J19: 2:55:00/13:15 | K19: 2:55:00 | L19: 13:15 | M19: 5:50:00/13:20 | N19: 5:50:00 | O19: 13:20 | P19: 14:05 | Q19: =QUOTIENT((_xlfn.TEXTBEFORE(B19,":")*$E$2+_xlfn.TEXTAFTER(B19,":"))/$D$2,$E$2)&":"&TEXT(MOD((_xlfn.TEXTBEFORE(B19,":")*$E$2+_xlfn.TEXTAFTER(B19,":"))/$D$2,$E$2),"00") -> 7:09 | R19: =_xlfn.TEXTBEFORE(Q19,":") -> 7 | S19: =_xlfn.TEXTAFTER(Q19,":") -> 09 | T19: =R19*60+S19 -> 429 | U19: =T20-T19 -> 18 | V19: =D19 -> 38:00 | W19: =_xlfn.TEXTBEFORE(V19,":") -> 38 | X19: =_xlfn.TEXTAFTER(V19,":") -> 00 | Y19: =W19*60+X19 -> 2280 | Z19: =IF(AND(Y19>$BR$8,SUM($Z$5:Z18)=0),1,0) -> 0 | AA19: =Y20-Y19 -> 90 | AB19: =IF(Z20=1,$BR$8-Y19,0) -> 0 | AC19: =AB19/AA19 -> 0 | AD19: =QUOTIENT((_xlfn.TEXTBEFORE(E19,":")*$E$2+_xlfn.TEXTAFTER(E19,":"))/$D$2,$E$2)&":"&TEXT(MOD((_xlfn.TEXTBEFORE(E19,":")*$E$2+_xlfn.TEXTAFTER(E19,":"))/$D$2,$E$2),"00") -> 7:37 | AE19: =_xlfn.TEXTBEFORE(AD19,":") -> 7 | AF19: =_xlfn.TEXTAFTER(AD19,":") -> 37 | AG19: =AE19*60+AF19 -> 457 | AH19: =AG20-AG19 -> 15 | AI19: =G19 -> 78:30 | AJ19: =QUOTIENT((_xlfn.TEXTBEFORE(H19,":")*$E$2+_xlfn.TEXTAFTER(H19,":"))/$D$2,$E$2)&":"&TEXT(MOD((_xlfn.TEXTBEFORE(H19,":")*$E$2+_xlfn.TEXTAFTER(H19,":"))/$D$2,$E$2),"00") -> 7:49 | AK19: =_xlfn.TEXTBEFORE(AJ19,":") -> 7 | AL19: =_xlfn.TEXTAFTER(AJ19,":") -> 49 | AM19: =AK19*60+AL19 -> 469 | AN19: =AM20-AM19 -> 19 | AO19: =QUOTIENT((_xlfn.TEXTBEFORE(I19,":")*$E$2+_xlfn.TEXTAFTER(I19,":"))/$D$2,$E$2)&":"&TEXT(MOD((_xlfn.TEXTBEFORE(I19,":")*$E$2+_xlfn.TEXTAFTER(I19,":"))/$D$2,$E$2),"00") -> 8:05 | AP19: =_xlfn.TEXTBEFORE(AO19,":") -> 8 | AQ19: =_xlfn.TEXTAFTER(AO19,":") -> 05 | AR19: =AP19*60+AQ19 -> 485 | AS19: =AR20-AR19 -> 21 | AT19: =K19 -> 2:55:00 | AU19: =QUOTIENT((_xlfn.TEXTBEFORE(L19,":")*$E$2+_xlfn.TEXTAFTER(L19,":"))/$D$2,$E$2)&":"&TEXT(MOD((_xlfn.TEXTBEFORE(L19,":")*$E$2+_xlfn.TEXTAFTER(L19,":"))/$D$2,$E$2),"00") -> 8:14 | AV19: =_xlfn.TEXTBEFORE(AU19,":") -> 8 | AW19: =_xlfn.TEXTAFTER(AU19,":") -> 14 | AX19: =AV19*60+AW19 -> 494 | AY19: =AX20-AX19 -> 31 | AZ19: =N19 -> 5:50:00 | BA19: =QUOTIENT((_xlfn.TEXTBEFORE(O19,":")*$E$2+_xlfn.TEXTAFTER(O19,":"))/$D$2,$E$2)&":"&TEXT(MOD((_xlfn.TEXTBEFORE(O19,":")*$E$2+_xlfn.TEXTAFTER(O19,":"))/$D$2,$E$2),"00") -> 8:17 | BB19: =_xlfn.TEXTBEFORE(BA19,":") -> 8 | BC19: =_xlfn.TEXTAFTER(BA19,":") -> 17 | BD19: =BB19*60+BC19 -> 497 | BE19: =BD20-BD19 -> 16 | BF19: =BB19*60+BC19 -> 497 | BG19: =QUOTIENT((_xlfn.TEXTBEFORE(P19,":")*$E$2+_xlfn.TEXTAFTER(P19,":"))/$D$2,$E$2)&":"&TEXT(MOD((_xlfn.TEXTBEFORE(P19,":")*$E$2+_xlfn.TEXTAFTER(P19,":"))/$D$2,$E$2),"00") -> 8:45 | BH19: =_xlfn.TEXTBEFORE(BG19,":") -> 8 | BI19: =_xlfn.TEXTAFTER(BG19,":") -> 45 | BJ19: =BH19*60+BI19 -> 525 | BK19: =BJ20-BJ19 -> 16
B20: 12:00 | C20: 39:30/12:40 | D20: 39:30 | E20: 12:40 | F20: 81:30/13:05 | G20: 81:30 | H20: 13:05 | I20: 13:35 | J20: 3:05:00/14:05 | K20: 3:05:00 | L20: 14:05 | M20: 6:00:00/13:45 | N20: 6:00:00 | O20: 13:45 | P20: 14:30 | Q20: =QUOTIENT((_xlfn.TEXTBEFORE(B20,":")*$E$2+_xlfn.TEXTAFTER(B20,":"))/$D$2,$E$2)&":"&TEXT(MOD((_xlfn.TEXTBEFORE(B20,":")*$E$2+_xlfn.TEXTAFTER(B20,":"))/$D$2,$E$2),"00") -> 7:27 | R20: =_xlfn.TEXTBEFORE(Q20,":") -> 7 | S20: =_xlfn.TEXTAFTER(Q20,":") -> 27 | T20: =R20*60+S20 -> 447 | V20: =D20 -> 39:30 | W20: =_xlfn.TEXTBEFORE(V20,":") -> 39 | X20: =_xlfn.TEXTAFTER(V20,":") -> 30 | Y20: =W20*60+X20 -> 2370 | Z20: =IF(AND(Y20>$BR$8,SUM($Z$5:Z19)=0),1,0) -> 0 | AD20: =QUOTIENT((_xlfn.TEXTBEFORE(E20,":")*$E$2+_xlfn.TEXTAFTER(E20,":"))/$D$2,$E$2)&":"&TEXT(MOD((_xlfn.TEXTBEFORE(E20,":")*$E$2+_xlfn.TEXTAFTER(E20,":"))/$D$2,$E$2),"00") -> 7:52 | AE20: =_xlfn.TEXTBEFORE(AD20,":") -> 7 | AF20: =_xlfn.TEXTAFTER(AD20,":") -> 52 | AG20: =AE20*60+AF20 -> 472 | AI20: =G20 -> 81:30 | AJ20: =QUOTIENT((_xlfn.TEXTBEFORE(H20,":")*$E$2+_xlfn.TEXTAFTER(H20,":"))/$D$2,$E$2)&":"&TEXT(MOD((_xlfn.TEXTBEFORE(H20,":")*$E$2+_xlfn.TEXTAFTER(H20,":"))/$D$2,$E$2),"00") -> 8:08 | AK20: =_xlfn.TEXTBEFORE(AJ20,":") -> 8 | AL20: =_xlfn.TEXTAFTER(AJ20,":") -> 08 | AM20: =AK20*60+AL20 -> 488 | AO20: =QUOTIENT((_xlfn.TEXTBEFORE(I20,":")*$E$2+_xlfn.TEXTAFTER(I20,":"))/$D$2,$E$2)&":"&TEXT(MOD((_xlfn.TEXTBEFORE(I20,":")*$E$2+_xlfn.TEXTAFTER(I20,":"))/$D$2,$E$2),"00") -> 8:26 | AP20: =_xlfn.TEXTBEFORE(AO20,":") -> 8 | AQ20: =_xlfn.TEXTAFTER(AO20,":") -> 26 | AR20: =AP20*60+AQ20 -> 506 | AT20: =K20 -> 3:05:00 | AU20: =QUOTIENT((_xlfn.TEXTBEFORE(L20,":")*$E$2+_xlfn.TEXTAFTER(L20,":"))/$D$2,$E$2)&":"&TEXT(MOD((_xlfn.TEXTBEFORE(L20,":")*$E$2+_xlfn.TEXTAFTER(L20,":"))/$D$2,$E$2),"00") -> 8:45 | AV20: =_xlfn.TEXTBEFORE(AU20,":") -> 8 | AW20: =_xlfn.TEXTAFTER(AU20,":") -> 45 | AX20: =AV20*60+AW20 -> 525 | AZ20: =N20 -> 6:00:00 | BA20: =QUOTIENT((_xlfn.TEXTBEFORE(O20,":")*$E$2+_xlfn.TEXTAFTER(O20,":"))/$D$2,$E$2)&":"&TEXT(MOD((_xlfn.TEXTBEFORE(O20,":")*$E$2+_xlfn.TEXTAFTER(O20,":"))/$D$2,$E$2),"00") -> 8:33 | BB20: =_xlfn.TEXTBEFORE(BA20,":") -> 8 | BC20: =_xlfn.TEXTAFTER(BA20,":") -> 33 | BD20: =BB20*60+BC20 -> 513 | BF20: =BB20*60+BC20 -> 513 | BG20: =QUOTIENT((_xlfn.TEXTBEFORE(P20,":")*$E$2+_xlfn.TEXTAFTER(P20,":"))/$D$2,$E$2)&":"&TEXT(MOD((_xlfn.TEXTBEFORE(P20,":")*$E$2+_xlfn.TEXTAFTER(P20,":"))/$D$2,$E$2),"00") -> 9:01 | BH20: =_xlfn.TEXTBEFORE(BG20,":") -> 9 | BI20: =_xlfn.TEXTAFTER(BG20,":") -> 01 | BJ20: =BH20*60+BI20 -> 541
BM24: 10k | BN24: Run | BO24: Avg.
BN25: 5k total | BO25: 30:00
BN26: Best | BO26: 05:36
BN27: Mile | BO27: 05:48 | BX27: 0.0064814815
BN28: 5k avg. | BO28: 06:00 | BX28: 0.020833333
BN29: 10k avg. | BO29: 06:13 | BX29: 0.043171296
BN30: Tempo | BO30: 06:31
BN31: Half avg. | BO31: 06:38 | BX31: 0.0971875
BN32: Full avg. | BO32: 06:44 | BX32: 0.19729167
BN33: Recovery | BO33: 07:12
BM35: 10k | BN35: Run | BO35: Avg.
BN36: 5k total | BO36: 25:00
BN37: Best | BO37: 04:37
BN38: Mile | BO38: 04:48 | BX38: 0.0053472222
BN39: 5k avg. | BO39: 04:59 | BX39: 0.017268519
BN40: 10k avg. | BO40: 05:11 | BX40: 0.035972222
BN41: Tempo | BO41: 05:26
BN42: Half avg. | BO42: 05:24 | BX42: 0.078993056
BN43: Full avg. | BO43: 05:38 | BX43: 0.16521991
BN44: Recovery | BO44: 06:06
BM46: Half | BN46: Run | BO46: Avg.
BN47: 5k total | BO47: 26:10
...

Sheet Individual pace
C2: Pace | G2: Avg. pace
B3: Split | C3: Seconds | D3: In format | E3: Pace up | F3: Last | G3: Total seconds | H3: Goal | I3: 5 | J3: 6.5 | K3: 8 | L3: 10 | M3: 3.5
